Workbook
Name Aparelho: Aparelhos!$A$2:$A$4
Name Cliente: Cliente!$A$2:$A$5
Name cores: Cores!$A$2:$A$10
Name Função: #REF!
Name Máquina: Máquinas!$A$2:$A$12
Name numero_ops: 'BD da OP'!$A$2:$A$3
Name Operações: Operações!$A$2:$A$21
Name Referência: Ref!$A$2:$A$5
Name tamanhos: Tamanhos!$A$2:$A$23

Sheet Menu
C18: Cópia autorizada para:
C19: KAMYLLA ATAYZA BEZERRA FERREIRA
C20: 8490676429
C23: © 2012 - Pedro Paulo Andriani. Todos os direitos reservados. | H23: Planilhas para Confecção
B24: Versão 1.0
G51: 73051
G52: =IF(G60=0,0,IF(G51<TODAY(),0,1)) -> 1
E54: =Menu!C19 -> KAMYLLA ATAYZA BEZERRA FERREIRA | G54: KAMYLLA ATAYZA BEZERRA FERREIRA
E55: =Menu!C20 -> 8490676429 | G55: 8490676429
G56: © 2012 - Pedro Paulo Andriani. Todos os direitos reservados.
G57: Planilhas para Confecção
G58: =CONCATENATE(G54,G55,G56,G57) -> KAMYLLA ATAYZA BEZERRA FERREIRA8490676429© 2012 - Pedro Paulo Andriani. Todos os direitos reservados. Planilhas para Confecção
G59: =CONCATENATE(Menu!C61,Menu!C62,Menu!C63,Menu!C64) -> KAMYLLA ATAYZA BEZERRA FERREIRA8490676429© 2012 - Pedro Paulo Andriani. Todos os direitos reservados. Planilhas para Confecção
G60: =IF(G58<>G59,0,1) -> 1
C61: =C19 -> KAMYLLA ATAYZA BEZERRA FERREIRA
C62: =C20 -> 8490676429
C63: =C23 -> © 2012 - Pedro Paulo Andriani. Todos os direitos reservados.
C64: =H23 -> Planilhas para Confecção

Sheet Seq. Operacional
C1: Sequência Operacional e Tempo Padrão | E1: Data cadastro: | F1: =TODAY() -> 46133 | N1: =IF(OR(F1=0,C2=0),0,1) -> 0
N2: =IF(OR(C6=0,C7=0),0,1) -> 0
C3: =IF(C2=0,"",VLOOKUP(C2,Ref!A:B,2,FALSE)) | N3: =IF(C2=0,"",IF(ISERROR(VLOOKUP(C2,'BD Seq Op'!B:H,1,FALSE)),"","Já cadastrada."))
A4: Filtro | B4: Seq. | C4: Descrição operacional | D4: Tipo Máq. | E4: Tipo Apar. | F4: Tempo Padrão
A5: Sim | B5: Seq. | C5: Descrição das Operações | D5: Tipo Máq. | E5: Tipo Apar. | F5: Tempo Padrão | H5: =IF(SUM(G6:G125)>0," ATENÇÃO! Você deixou alguma linha acima em branco, não é permitido.","") | N5: =IF(N3="Já cadastrada.","- - -",IF(SUM(N6:N125)>0,"- - -",IF(N1+N2=2,"Cadastrar","- - -"))) -> - - -
A6: =IF(C6=0,"Não","Sim") -> Não | B6: 10 | D6: =IF(C6=0,0,IF(ISERROR(VLOOKUP(C6,Operações!A:D,2,FALSE)),0,VLOOKUP(C6,Operações!A:D,2,FALSE))) -> 0 | E6: =IF(C6=0,0,IF(ISERROR(VLOOKUP(C6,Operações!A:D,3,FALSE)),0,VLOOKUP(C6,Operações!A:D,3,FALSE))) -> 0 | F6: =IF(C6=0,0,IF(ISERROR(VLOOKUP(C6,Operações!A:D,4,FALSE)),0,VLOOKUP(C6,Operações!A:D,4,FALSE))) -> 0 | N6: =IF(C6=0,0,IF(AND(D6<>0,F6<>0),0,1)) -> 0
A7: =IF(C7=0,"Não","Sim") -> Não | B7: 20 | D7: =IF(C7=0,0,IF(ISERROR(VLOOKUP(C7,Operações!A:D,2,FALSE)),0,VLOOKUP(C7,Operações!A:D,2,FALSE))) -> 0 | E7: =IF(C7=0,0,IF(ISERROR(VLOOKUP(C7,Operações!A:D,3,FALSE)),0,VLOOKUP(C7,Operações!A:D,3,FALSE))) -> 0 | F7: =IF(C7=0,0,IF(ISERROR(VLOOKUP(C7,Operações!A:D,4,FALSE)),0,VLOOKUP(C7,Operações!A:D,4,FALSE))) -> 0 | G7: =IF(AND(C6=0,C7<>0),1,0) -> 0 | N7: =IF(C7=0,0,IF(AND(D7<>0,F7<>0),0,1)) -> 0
A8: =IF(C8=0,"Não","Sim") -> Não | B8: 30 | D8: =IF(C8=0,0,IF(ISERROR(VLOOKUP(C8,Operações!A:D,2,FALSE)),0,VLOOKUP(C8,Operações!A:D,2,FALSE))) -> 0 | E8: =IF(C8=0,0,IF(ISERROR(VLOOKUP(C8,Operações!A:D,3,FALSE)),0,VLOOKUP(C8,Operações!A:D,3,FALSE))) -> 0 | F8: =IF(C8=0,0,IF(ISERROR(VLOOKUP(C8,Operações!A:D,4,FALSE)),0,VLOOKUP(C8,Operações!A:D,4,FALSE))) -> 0 | G8: =IF(AND(C7=0,C8<>0),1,0) -> 0 | N8: =IF(C8=0,0,IF(AND(D8<>0,F8<>0),0,1)) -> 0
A9: =IF(C9=0,"Não","Sim") -> Não | B9: 40 | D9: =IF(C9=0,0,IF(ISERROR(VLOOKUP(C9,Operações!A:D,2,FALSE)),0,VLOOKUP(C9,Operações!A:D,2,FALSE))) -> 0 | E9: =IF(C9=0,0,IF(ISERROR(VLOOKUP(C9,Operações!A:D,3,FALSE)),0,VLOOKUP(C9,Operações!A:D,3,FALSE))) -> 0 | F9: =IF(C9=0,0,IF(ISERROR(VLOOKUP(C9,Operações!A:D,4,FALSE)),0,VLOOKUP(C9,Operações!A:D,4,FALSE))) -> 0 | G9: =IF(AND(C8=0,C9<>0),1,0) -> 0 | N9: =IF(C9=0,0,IF(AND(D9<>0,F9<>0),0,1)) -> 0
A10: =IF(C10=0,"Não","Sim") -> Não | B10: 50 | D10: =IF(C10=0,0,IF(ISERROR(VLOOKUP(C10,Operações!A:D,2,FALSE)),0,VLOOKUP(C10,Operações!A:D,2,FALSE))) -> 0 | E10: =IF(C10=0,0,IF(ISERROR(VLOOKUP(C10,Operações!A:D,3,FALSE)),0,VLOOKUP(C10,Operações!A:D,3,FALSE))) -> 0 | F10: =IF(C10=0,0,IF(ISERROR(VLOOKUP(C10,Operações!A:D,4,FALSE)),0,VLOOKUP(C10,Operações!A:D,4,FALSE))) -> 0 | G10: =IF(AND(C9=0,C10<>0),1,0) -> 0 | N10: =IF(C10=0,0,IF(AND(D10<>0,F10<>0),0,1)) -> 0
A11: =IF(C11=0,"Não","Sim") -> Não | B11: 60 | D11: =IF(C11=0,0,IF(ISERROR(VLOOKUP(C11,Operações!A:D,2,FALSE)),0,VLOOKUP(C11,Operações!A:D,2,FALSE))) -> 0 | E11: =IF(C11=0,0,IF(ISERROR(VLOOKUP(C11,Operações!A:D,3,FALSE)),0,VLOOKUP(C11,Operações!A:D,3,FALSE))) -> 0 | F11: =IF(C11=0,0,IF(ISERROR(VLOOKUP(C11,Operações!A:D,4,FALSE)),0,VLOOKUP(C11,Operações!A:D,4,FALSE))) -> 0 | G11: =IF(AND(C10=0,C11<>0),1,0) -> 0 | N11: =IF(C11=0,0,IF(AND(D11<>0,F11<>0),0,1)) -> 0
A12: =IF(C12=0,"Não","Sim") -> Não | B12: 70 | D12: =IF(C12=0,0,IF(ISERROR(VLOOKUP(C12,Operações!A:D,2,FALSE)),0,VLOOKUP(C12,Operações!A:D,2,FALSE))) -> 0 | E12: =IF(C12=0,0,IF(ISERROR(VLOOKUP(C12,Operações!A:D,3,FALSE)),0,VLOOKUP(C12,Operações!A:D,3,FALSE))) -> 0 | F12: =IF(C12=0,0,IF(ISERROR(VLOOKUP(C12,Operações!A:D,4,FALSE)),0,VLOOKUP(C12,Operações!A:D,4,FALSE))) -> 0 | G12: =IF(AND(C11=0,C12<>0),1,0) -> 0 | N12: =IF(C12=0,0,IF(AND(D12<>0,F12<>0),0,1)) -> 0
A13: =IF(C13=0,"Não","Sim") -> Não | B13: 80 | D13: =IF(C13=0,0,IF(ISERROR(VLOOKUP(C13,Operações!A:D,2,FALSE)),0,VLOOKUP(C13,Operações!A:D,2,FALSE))) -> 0 | E13: =IF(C13=0,0,IF(ISERROR(VLOOKUP(C13,Operações!A:D,3,FALSE)),0,VLOOKUP(C13,Operações!A:D,3,FALSE))) -> 0 | F13: =IF(C13=0,0,IF(ISERROR(VLOOKUP(C13,Operações!A:D,4,FALSE)),0,VLOOKUP(C13,Operações!A:D,4,FALSE))) -> 0 | G13: =IF(AND(C12=0,C13<>0),1,0) -> 0 | N13: =IF(C13=0,0,IF(AND(D13<>0,F13<>0),0,1)) -> 0
A14: =IF(C14=0,"Não","Sim") -> Não | B14: 90 | D14: =IF(C14=0,0,IF(ISERROR(VLOOKUP(C14,Operações!A:D,2,FALSE)),0,VLOOKUP(C14,Operações!A:D,2,FALSE))) -> 0 | E14: =IF(C14=0,0,IF(ISERROR(VLOOKUP(C14,Operações!A:D,3,FALSE)),0,VLOOKUP(C14,Operações!A:D,3,FALSE))) -> 0 | F14: =IF(C14=0,0,IF(ISERROR(VLOOKUP(C14,Operações!A:D,4,FALSE)),0,VLOOKUP(C14,Operações!A:D,4,FALSE))) -> 0 | G14: =IF(AND(C13=0,C14<>0),1,0) -> 0 | N14: =IF(C14=0,0,IF(AND(D14<>0,F14<>0),0,1)) -> 0
A15: =IF(C15=0,"Não","Sim") -> Não | B15: 100 | D15: =IF(C15=0,0,IF(ISERROR(VLOOKUP(C15,Operações!A:D,2,FALSE)),0,VLOOKUP(C15,Operações!A:D,2,FALSE))) -> 0 | E15: =IF(C15=0,0,IF(ISERROR(VLOOKUP(C15,Operações!A:D,3,FALSE)),0,VLOOKUP(C15,Operações!A:D,3,FALSE))) -> 0 | F15: =IF(C15=0,0,IF(ISERROR(VLOOKUP(C15,Operações!A:D,4,FALSE)),0,VLOOKUP(C15,Operações!A:D,4,FALSE))) -> 0 | G15: =IF(AND(C14=0,C15<>0),1,0) -> 0 | N15: =IF(C15=0,0,IF(AND(D15<>0,F15<>0),0,1)) -> 0
A16: =IF(C16=0,"Não","Sim") -> Não | B16: 110 | D16: =IF(C16=0,0,IF(ISERROR(VLOOKUP(C16,Operações!A:D,2,FALSE)),0,VLOOKUP(C16,Operações!A:D,2,FALSE))) -> 0 | E16: =IF(C16=0,0,IF(ISERROR(VLOOKUP(C16,Operações!A:D,3,FALSE)),0,VLOOKUP(C16,Operações!A:D,3,FALSE))) -> 0 | F16: =IF(C16=0,0,IF(ISERROR(VLOOKUP(C16,Operações!A:D,4,FALSE)),0,VLOOKUP(C16,Operações!A:D,4,FALSE))) -> 0 | G16: =IF(AND(C15=0,C16<>0),1,0) -> 0 | N16: =IF(C16=0,0,IF(AND(D16<>0,F16<>0),0,1)) -> 0
A17: =IF(C17=0,"Não","Sim") -> Não | B17: 120 | D17: =IF(C17=0,0,IF(ISERROR(VLOOKUP(C17,Operações!A:D,2,FALSE)),0,VLOOKUP(C17,Operações!A:D,2,FALSE))) -> 0 | E17: =IF(C17=0,0,IF(ISERROR(VLOOKUP(C17,Operações!A:D,3,FALSE)),0,VLOOKUP(C17,Operações!A:D,3,FALSE))) -> 0 | F17: =IF(C17=0,0,IF(ISERROR(VLOOKUP(C17,Operações!A:D,4,FALSE)),0,VLOOKUP(C17,Operações!A:D,4,FALSE))) -> 0 | G17: =IF(AND(C16=0,C17<>0),1,0) -> 0 | N17: =IF(C17=0,0,IF(AND(D17<>0,F17<>0),0,1)) -> 0
A18: =IF(C18=0,"Não","Sim") -> Não | B18: 130 | D18: =IF(C18=0,0,IF(ISERROR(VLOOKUP(C18,Operações!A:D,2,FALSE)),0,VLOOKUP(C18,Operações!A:D,2,FALSE))) -> 0 | E18: =IF(C18=0,0,IF(ISERROR(VLOOKUP(C18,Operações!A:D,3,FALSE)),0,VLOOKUP(C18,Operações!A:D,3,FALSE))) -> 0 | F18: =IF(C18=0,0,IF(ISERROR(VLOOKUP(C18,Operações!A:D,4,FALSE)),0,VLOOKUP(C18,Operações!A:D,4,FALSE))) -> 0 | G18: =IF(AND(C17=0,C18<>0),1,0) -> 0 | N18: =IF(C18=0,0,IF(AND(D18<>0,F18<>0),0,1)) -> 0
... A125: =IF(C125=0,"Não","Sim") -> Não | B125: 1200 | D125: =IF(C125=0,0,IF(ISERROR(VLOOKUP(C125,Operações!A:D,2,FALSE)),0,VLOOKUP(C125,Operações!A:D,2,FALSE))) -> 0 | E125: =IF(C125=0,0,IF(ISERROR(VLOOKUP(C125,Operações!A:D,3,FALSE)),0,VLOOKUP(C125,Operações!A:D,3,FALSE))) -> 0 | F125: =IF(C125=0,0,IF(ISERROR(VLOOKUP(C125,Operações!A:D,4,FALSE)),0,VLOOKUP(C125,Operações!A:D,4,FALSE))) -> 0 | G125: =IF(AND(C124=0,C125<>0),1,0) -> 0 | N125: =IF(C125=0,0,IF(AND(D125<>0,F125<>0),0,1)) -> 0
A126: Sim | E126: Tempo Total => | F126: =SUM(F6:F125) -> 0
D130: =IF(C130=0,0,IF(ISERROR(VLOOKUP(C130,Operações!A:D,2,FALSE)),0,VLOOKUP(C130,Operações!A:D,2,FALSE))) -> 0 | E130: =IF(C130=0,0,IF(ISERROR(VLOOKUP(C130,Operações!A:D,3,FALSE)),0,VLOOKUP(C130,Operações!A:D,3,FALSE))) -> 0 | F130: =IF(C130=0,0,IF(ISERROR(VLOOKUP(C130,Operações!A:D,4,FALSE)),0,VLOOKUP(C130,Operações!A:D,4,FALSE))) -> 0

Sheet Transf Seq Op.
B1: ='Seq. Operacional'!$C$2 -> 0 | C1: =CONCATENATE(B1,"-",A1) -> 0- | H1: ='Seq. Operacional'!$F$1 -> 46133 | I1: =IF(E1=0,0,CONCATENATE(B1,"-",E1)) -> 0 | J1: =IF(F1=0,0,CONCATENATE(B1,"-",F1)) -> 0
A2: Seq. | B2: Ref. | C2: Concatenar | D2: Descrição das Operações | E2: Tipo Máq. | F2: Tipo Apar. | G2: Tempo Padrão | H2: Data do Cadastro | I2: Somase Máquina | J2: Somase Aparelho

Sheet Consulta Seq. Operacional
C1: Sequência Operacional e Tempo Padrão | E1: Data cadastro: | F1: =IF($C$2=0,"",IF(ISERROR(VLOOKUP($C$2&"-"&B6,'BD Seq Op'!C:H,6,FALSE)),"",VLOOKUP($C$2&"-"&B6,'BD Seq Op'!C:H,6,FALSE))) | N1: =IF(C2=0,"",IF(ISERROR(VLOOKUP(C2&"-"&B6,'BD Seq Op'!C:H,6,FALSE)),"Não cadastrada.","")) -> Não cadastrada.
C2: 10000
C3: =IF(C2=0,"",IF(N1="Não cadastrada.","",VLOOKUP(C2,Ref!A:B,2,FALSE)))
A4: Filtro | B4: Seq. | C4: Descrição operacional | D4: Tipo Máq. | E4: Tipo Apar. | F4: Tempo Padrão
A5: Sim | B5: Seq. | C5: Descrição das Operações | D5: Tipo Máq. | E5: Tipo Apar. | F5: Tempo Padrão
A6: =IF(C6="","Não","Sim") -> Não | B6: 1 | C6: =IF($C$2=0,"",IF(ISERROR(VLOOKUP($C$2&"-"&$B6,'BD Seq Op'!$C:$H,2,FALSE)),"",VLOOKUP($C$2&"-"&$B6,'BD Seq Op'!$C:$H,2,FALSE))) | D6: =IF($C$2=0,"",IF(ISERROR(VLOOKUP($C$2&"-"&$B6,'BD Seq Op'!$C:$H,3,FALSE)),"",VLOOKUP($C$2&"-"&$B6,'BD Seq Op'!$C:$H,3,FALSE))) | E6: =IF($C$2=0,"",IF(ISERROR(VLOOKUP($C$2&"-"&$B6,'BD Seq Op'!$C:$H,4,FALSE)),"",VLOOKUP($C$2&"-"&$B6,'BD Seq Op'!$C:$H,4,FALSE))) | F6: =IF($C$2=0,"",IF(ISERROR(VLOOKUP($C$2&"-"&$B6,'BD Seq Op'!$C:$H,5,FALSE)),"",VLOOKUP($C$2&"-"&$B6,'BD Seq Op'!$C:$H,5,FALSE)))
A7: =IF(C7="","Não","Sim") -> Não | B7: 2 | C7: =IF($C$2=0,"",IF(ISERROR(VLOOKUP($C$2&"-"&$B7,'BD Seq Op'!$C:$H,2,FALSE)),"",VLOOKUP($C$2&"-"&$B7,'BD Seq Op'!$C:$H,2,FALSE))) | D7: =IF($C$2=0,"",IF(ISERROR(VLOOKUP($C$2&"-"&$B7,'BD Seq Op'!$C:$H,3,FALSE)),"",VLOOKUP($C$2&"-"&$B7,'BD Seq Op'!$C:$H,3,FALSE))) | E7: =IF($C$2=0,"",IF(ISERROR(VLOOKUP($C$2&"-"&$B7,'BD Seq Op'!$C:$H,4,FALSE)),"",VLOOKUP($C$2&"-"&$B7,'BD Seq Op'!$C:$H,4,FALSE))) | F7: =IF($C$2=0,"",IF(ISERROR(VLOOKUP($C$2&"-"&$B7,'BD Seq Op'!$C:$H,5,FALSE)),"",VLOOKUP($C$2&"-"&$B7,'BD Seq Op'!$C:$H,5,FALSE)))
A8: =IF(C8="","Não","Sim") -> Não | B8: 3 | C8: =IF($C$2=0,"",IF(ISERROR(VLOOKUP($C$2&"-"&$B8,'BD Seq Op'!$C:$H,2,FALSE)),"",VLOOKUP($C$2&"-"&$B8,'BD Seq Op'!$C:$H,2,FALSE))) | D8: =IF($C$2=0,"",IF(ISERROR(VLOOKUP($C$2&"-"&$B8,'BD Seq Op'!$C:$H,3,FALSE)),"",VLOOKUP($C$2&"-"&$B8,'BD Seq Op'!$C:$H,3,FALSE))) | E8: =IF($C$2=0,"",IF(ISERROR(VLOOKUP($C$2&"-"&$B8,'BD Seq Op'!$C:$H,4,FALSE)),"",VLOOKUP($C$2&"-"&$B8,'BD Seq Op'!$C:$H,4,FALSE))) | F8: =IF($C$2=0,"",IF(ISERROR(VLOOKUP($C$2&"-"&$B8,'BD Seq Op'!$C:$H,5,FALSE)),"",VLOOKUP($C$2&"-"&$B8,'BD Seq Op'!$C:$H,5,FALSE)))
A9: =IF(C9="","Não","Sim") -> Não | B9: 4 | C9: =IF($C$2=0,"",IF(ISERROR(VLOOKUP($C$2&"-"&$B9,'BD Seq Op'!$C:$H,2,FALSE)),"",VLOOKUP($C$2&"-"&$B9,'BD Seq Op'!$C:$H,2,FALSE))) | D9: =IF($C$2=0,"",IF(ISERROR(VLOOKUP($C$2&"-"&$B9,'BD Seq Op'!$C:$H,3,FALSE)),"",VLOOKUP($C$2&"-"&$B9,'BD Seq Op'!$C:$H,3,FALSE))) | E9: =IF($C$2=0,"",IF(ISERROR(VLOOKUP($C$2&"-"&$B9,'BD Seq Op'!$C:$H,4,FALSE)),"",VLOOKUP($C$2&"-"&$B9,'BD Seq Op'!$C:$H,4,FALSE))) | F9: =IF($C$2=0,"",IF(ISERROR(VLOOKUP($C$2&"-"&$B9,'BD Seq Op'!$C:$H,5,FALSE)),"",VLOOKUP($C$2&"-"&$B9,'BD Seq Op'!$C:$H,5,FALSE)))
A10: =IF(C10="","Não","Sim") -> Não | B10: 5 | C10: =IF($C$2=0,"",IF(ISERROR(VLOOKUP($C$2&"-"&$B10,'BD Seq Op'!$C:$H,2,FALSE)),"",VLOOKUP($C$2&"-"&$B10,'BD Seq Op'!$C:$H,2,FALSE))) | D10: =IF($C$2=0,"",IF(ISERROR(VLOOKUP($C$2&"-"&$B10,'BD Seq Op'!$C:$H,3,FALSE)),"",VLOOKUP($C$2&"-"&$B10,'BD Seq Op'!$C:$H,3,FALSE))) | E10: =IF($C$2=0,"",IF(ISERROR(VLOOKUP($C$2&"-"&$B10,'BD Seq Op'!$C:$H,4,FALSE)),"",VLOOKUP($C$2&"-"&$B10,'BD Seq Op'!$C:$H,4,FALSE))) | F10: =IF($C$2=0,"",IF(ISERROR(VLOOKUP($C$2&"-"&$B10,'BD Seq Op'!$C:$H,5,FALSE)),"",VLOOKUP($C$2&"-"&$B10,'BD Seq Op'!$C:$H,5,FALSE)))
A11: =IF(C11="","Não","Sim") -> Não | B11: 6 | C11: =IF($C$2=0,"",IF(ISERROR(VLOOKUP($C$2&"-"&$B11,'BD Seq Op'!$C:$H,2,FALSE)),"",VLOOKUP($C$2&"-"&$B11,'BD Seq Op'!$C:$H,2,FALSE))) | D11: =IF($C$2=0,"",IF(ISERROR(VLOOKUP($C$2&"-"&$B11,'BD Seq Op'!$C:$H,3,FALSE)),"",VLOOKUP($C$2&"-"&$B11,'BD Seq Op'!$C:$H,3,FALSE))) | E11: =IF($C$2=0,"",IF(ISERROR(VLOOKUP($C$2&"-"&$B11,'BD Seq Op'!$C:$H,4,FALSE)),"",VLOOKUP($C$2&"-"&$B11,'BD Seq Op'!$C:$H,4,FALSE))) | F11: =IF($C$2=0,"",IF(ISERROR(VLOOKUP($C$2&"-"&$B11,'BD Seq Op'!$C:$H,5,FALSE)),"",VLOOKUP($C$2&"-"&$B11,'BD Seq Op'!$C:$H,5,FALSE)))
A12: =IF(C12="","Não","Sim") -> Não | B12: 7 | C12: =IF($C$2=0,"",IF(ISERROR(VLOOKUP($C$2&"-"&$B12,'BD Seq Op'!$C:$H,2,FALSE)),"",VLOOKUP($C$2&"-"&$B12,'BD Seq Op'!$C:$H,2,FALSE))) | D12: =IF($C$2=0,"",IF(ISERROR(VLOOKUP($C$2&"-"&$B12,'BD Seq Op'!$C:$H,3,FALSE)),"",VLOOKUP($C$2&"-"&$B12,'BD Seq Op'!$C:$H,3,FALSE))) | E12: =IF($C$2=0,"",IF(ISERROR(VLOOKUP($C$2&"-"&$B12,'BD Seq Op'!$C:$H,4,FALSE)),"",VLOOKUP($C$2&"-"&$B12,'BD Seq Op'!$C:$H,4,FALSE))) | F12: =IF($C$2=0,"",IF(ISERROR(VLOOKUP($C$2&"-"&$B12,'BD Seq Op'!$C:$H,5,FALSE)),"",VLOOKUP($C$2&"-"&$B12,'BD Seq Op'!$C:$H,5,FALSE)))
A13: =IF(C13="","Não","Sim") -> Não | B13: 8 | C13: =IF($C$2=0,"",IF(ISERROR(VLOOKUP($C$2&"-"&$B13,'BD Seq Op'!$C:$H,2,FALSE)),"",VLOOKUP($C$2&"-"&$B13,'BD Seq Op'!$C:$H,2,FALSE))) | D13: =IF($C$2=0,"",IF(ISERROR(VLOOKUP($C$2&"-"&$B13,'BD Seq Op'!$C:$H,3,FALSE)),"",VLOOKUP($C$2&"-"&$B13,'BD Seq Op'!$C:$H,3,FALSE))) | E13: =IF($C$2=0,"",IF(ISERROR(VLOOKUP($C$2&"-"&$B13,'BD Seq Op'!$C:$H,4,FALSE)),"",VLOOKUP($C$2&"-"&$B13,'BD Seq Op'!$C:$H,4,FALSE))) | F13: =IF($C$2=0,"",IF(ISERROR(VLOOKUP($C$2&"-"&$B13,'BD Seq Op'!$C:$H,5,FALSE)),"",VLOOKUP($C$2&"-"&$B13,'BD Seq Op'!$C:$H,5,FALSE)))
A14: =IF(C14="","Não","Sim") -> Não | B14: 9 | C14: =IF($C$2=0,"",IF(ISERROR(VLOOKUP($C$2&"-"&$B14,'BD Seq Op'!$C:$H,2,FALSE)),"",VLOOKUP($C$2&"-"&$B14,'BD Seq Op'!$C:$H,2,FALSE))) | D14: =IF($C$2=0,"",IF(ISERROR(VLOOKUP($C$2&"-"&$B14,'BD Seq Op'!$C:$H,3,FALSE)),"",VLOOKUP($C$2&"-"&$B14,'BD Seq Op'!$C:$H,3,FALSE))) | E14: =IF($C$2=0,"",IF(ISERROR(VLOOKUP($C$2&"-"&$B14,'BD Seq Op'!$C:$H,4,FALSE)),"",VLOOKUP($C$2&"-"&$B14,'BD Seq Op'!$C:$H,4,FALSE))) | F14: =IF($C$2=0,"",IF(ISERROR(VLOOKUP($C$2&"-"&$B14,'BD Seq Op'!$C:$H,5,FALSE)),"",VLOOKUP($C$2&"-"&$B14,'BD Seq Op'!$C:$H,5,FALSE)))
A15: =IF(C15="","Não","Sim") -> Não | B15: 10 | C15: =IF($C$2=0,"",IF(ISERROR(VLOOKUP($C$2&"-"&$B15,'BD Seq Op'!$C:$H,2,FALSE)),"",VLOOKUP($C$2&"-"&$B15,'BD Seq Op'!$C:$H,2,FALSE))) | D15: =IF($C$2=0,"",IF(ISERROR(VLOOKUP($C$2&"-"&$B15,'BD Seq Op'!$C:$H,3,FALSE)),"",VLOOKUP($C$2&"-"&$B15,'BD Seq Op'!$C:$H,3,FALSE))) | E15: =IF($C$2=0,"",IF(ISERROR(VLOOKUP($C$2&"-"&$B15,'BD Seq Op'!$C:$H,4,FALSE)),"",VLOOKUP($C$2&"-"&$B15,'BD Seq Op'!$C:$H,4,FALSE))) | F15: =IF($C$2=0,"",IF(ISERROR(VLOOKUP($C$2&"-"&$B15,'BD Seq Op'!$C:$H,5,FALSE)),"",VLOOKUP($C$2&"-"&$B15,'BD Seq Op'!$C:$H,5,FALSE)))
A16: =IF(C16="","Não","Sim") -> Não | B16: 11 | C16: =IF($C$2=0,"",IF(ISERROR(VLOOKUP($C$2&"-"&$B16,'BD Seq Op'!$C:$H,2,FALSE)),"",VLOOKUP($C$2&"-"&$B16,'BD Seq Op'!$C:$H,2,FALSE))) | D16: =IF($C$2=0,"",IF(ISERROR(VLOOKUP($C$2&"-"&$B16,'BD Seq Op'!$C:$H,3,FALSE)),"",VLOOKUP($C$2&"-"&$B16,'BD Seq Op'!$C:$H,3,FALSE))) | E16: =IF($C$2=0,"",IF(ISERROR(VLOOKUP($C$2&"-"&$B16,'BD Seq Op'!$C:$H,4,FALSE)),"",VLOOKUP($C$2&"-"&$B16,'BD Seq Op'!$C:$H,4,FALSE))) | F16: =IF($C$2=0,"",IF(ISERROR(VLOOKUP($C$2&"-"&$B16,'BD Seq Op'!$C:$H,5,FALSE)),"",VLOOKUP($C$2&"-"&$B16,'BD Seq Op'!$C:$H,5,FALSE)))
A17: =IF(C17="","Não","Sim") -> Não | B17: 12 | C17: =IF($C$2=0,"",IF(ISERROR(VLOOKUP($C$2&"-"&$B17,'BD Seq Op'!$C:$H,2,FALSE)),"",VLOOKUP($C$2&"-"&$B17,'BD Seq Op'!$C:$H,2,FALSE))) | D17: =IF($C$2=0,"",IF(ISERROR(VLOOKUP($C$2&"-"&$B17,'BD Seq Op'!$C:$H,3,FALSE)),"",VLOOKUP($C$2&"-"&$B17,'BD Seq Op'!$C:$H,3,FALSE))) | E17: =IF($C$2=0,"",IF(ISERROR(VLOOKUP($C$2&"-"&$B17,'BD Seq Op'!$C:$H,4,FALSE)),"",VLOOKUP($C$2&"-"&$B17,'BD Seq Op'!$C:$H,4,FALSE))) | F17: =IF($C$2=0,"",IF(ISERROR(VLOOKUP($C$2&"-"&$B17,'BD Seq Op'!$C:$H,5,FALSE)),"",VLOOKUP($C$2&"-"&$B17,'BD Seq Op'!$C:$H,5,FALSE)))
... A125: =IF(C125="","Não","Sim") -> Não | B125: 120 | C125: =IF($C$2=0,"",IF(ISERROR(VLOOKUP($C$2&"-"&$B125,'BD Seq Op'!$C:$H,2,FALSE)),"",VLOOKUP($C$2&"-"&$B125,'BD Seq Op'!$C:$H,2,FALSE))) | D125: =IF($C$2=0,"",IF(ISERROR(VLOOKUP($C$2&"-"&$B125,'BD Seq Op'!$C:$H,3,FALSE)),"",VLOOKUP($C$2&"-"&$B125,'BD Seq Op'!$C:$H,3,FALSE))) | E125: =IF($C$2=0,"",IF(ISERROR(VLOOKUP($C$2&"-"&$B125,'BD Seq Op'!$C:$H,4,FALSE)),"",VLOOKUP($C$2&"-"&$B125,'BD Seq Op'!$C:$H,4,FALSE))) | F125: =IF($C$2=0,"",IF(ISERROR(VLOOKUP($C$2&"-"&$B125,'BD Seq Op'!$C:$H,5,FALSE)),"",VLOOKUP($C$2&"-"&$B125,'BD Seq Op'!$C:$H,5,FALSE)))
A126: Sim | E126: Tempo Total => | F126: =SUM(F6:F125) -> 0
D130: =IF(C130=0,"",IF(ISERROR(VLOOKUP(C130,Operações!A:D,2,FALSE)),"-",VLOOKUP(C130,Operações!A:D,2,FALSE))) | E130: =IF(C130=0,"",IF(ISERROR(VLOOKUP(C130,Operações!A:D,3,FALSE)),"-",VLOOKUP(C130,Operações!A:D,3,FALSE))) | F130: =IF(C130=0,"",IF(ISERROR(VLOOKUP(C130,Operações!A:D,4,FALSE)),"-",VLOOKUP(C130,Operações!A:D,4,FALSE)))

Sheet BD Seq Op
A1: Seq. . | B1: Ref. | C1: Concatenar | D1: Descrição das Operações | E1: Tipo Máq. | F1: Tipo Apar. | G1: Tempo Padrão | H1: Data do Cadastro | I1: Somase Máquina | J1: Somase Aparelho
A2: 0 | B2: 0 | C2: =CONCATENATE(B2,"-",A2) -> 0-0 | D2: 0 | I2: =IF(E2=0,0,CONCATENATE(B2,"-",E2)) -> 0 | J2: =IF(F2=0,0,CONCATENATE(B2,"-",F2)) -> 0

Sheet Ficha Acompanhamento
G1: =IF(U1=TRUE,"Tempo para Produzir","") | M1: Cor : | U1: FALSE
G2: =IF(U1=TRUE,"Operador(a)","") | H2: =IF(U1=TRUE,"Dias","") | I2: =IF(U1=TRUE,"+ Horas","") | K2: Qtde Peças : | M2: Tam. : | U2: FALSE
G3: =IF(U1=TRUE,L5,"") | H3: =IF(G3="","",IF(OR(L5=0,M5=0),0,V5)) | I3: =IF(G3="","",AB5)
K4: Total Min. | L4: Operador(a) | M4: Min./dia | N4: Dias | O4: + Horas | P4: Qtde peças
K5: =F129 -> 0 | N5: =V5 -> 0 | O5: =AB5 -> 0:00 | U5: =IF(OR(L5=0,M5=0),0,K5/(L5*M5)) -> 0 | V5: =ROUNDDOWN(U5,0) -> 0 | W5: =U5-V5 -> 0 | X5: =(W5*M5)/60 -> 0 | Y5: =ROUNDDOWN(X5,0) -> 0 | Z5: =(X5-Y5)*60 -> 0 | AA5: =ROUNDDOWN(Z5,0) -> 0 | AB5: =IF(AA5<10,Y5&":0"&AA5,Y5&":"&AA5) -> 0:00
B6: =S18 | P6: =IF(AND(P5=0,U1=TRUE),"Informe a qtde de peças.","")
A7: Filtro | B7: Seq. | C7: Descrição das operações | D7: Tempo Padrão | E7: Pçs/h 100% | F7: Código Costureira | G7: Código Costureira | H7: Qtde Peças | I7: Tempo / Pacote
A8: Sim | B8: Seq. | C8: Descrição das Operações | D8: Tempo Padrão | E8: Pçs/h 100% | F8: Código Operador(a) | G8: Código Operador(a) | H8: Qtde Peças | I8: Tempo / Pacote
A9: =IF(C9=0,"Não","Sim") -> Não | B9: 1 | C9: =IF($L$1=0,0,IF(ISERROR(VLOOKUP($U$11&"-"&B9,'BD Seq Op'!C:H,2,FALSE)),0,VLOOKUP($U$11&"-"&B9,'BD Seq Op'!C:H,2,FALSE))) -> 0 | D9: =IF($L$1=0,0,IF(ISERROR(VLOOKUP($U$11&"-"&B9,'BD Seq Op'!C:H,5,FALSE)),0,VLOOKUP($U$11&"-"&B9,'BD Seq Op'!C:H,5,FALSE))) -> 0 | E9: =IF(C9=0,"",IF($U$1=TRUE,(60*$L$5)/D9,60/D9)) | H9: =IF(C9=0,"",IF($U$1=TRUE,$P$5,IF($L$2=0,$V$15,$L$2))) | I9: =IF(C9=0,"",IF(AE9=TRUE,0,D9*H9)) | R9: Nº OP : | S9: =IF(L1=0,"",CONCATENATE(R9,U9)) | U9: =IF(L1=0,"",L1) | AE9: FALSE
A10: =IF(C10=0,"Não","Sim") -> Não | B10: 2 | C10: =IF($L$1=0,0,IF(ISERROR(VLOOKUP($U$11&"-"&B10,'BD Seq Op'!C:H,2,FALSE)),0,VLOOKUP($U$11&"-"&B10,'BD Seq Op'!C:H,2,FALSE))) -> 0 | D10: =IF($L$1=0,0,IF(ISERROR(VLOOKUP($U$11&"-"&B10,'BD Seq Op'!C:H,5,FALSE)),0,VLOOKUP($U$11&"-"&B10,'BD Seq Op'!C:H,5,FALSE))) -> 0 | E10: =IF(C10=0,"",IF($U$1=TRUE,(60*$L$5)/D10,60/D10)) | H10: =IF(C10=0,"",IF($U$1=TRUE,$P$5,IF($L$2=0,$V$15,$L$2))) | I10: =IF(C10=0,"",IF(AE10=TRUE,0,D10*H10)) | R10: Data Emissão : | S10: =IF(L1=0,"",IF(U10=0,R10,CONCATENATE(R10,TEXT(U10,"dd/mm/aaaa")))) | U10: =IF($L$1=0,"",IF(ISERROR(VLOOKUP($L$1,'BD da OP'!$A:$AC,3,FALSE)),"",VLOOKUP($L$1,'BD da OP'!$A:$AC,3,FALSE))) | AE10: FALSE
A11: =IF(C11=0,"Não","Sim") -> Não | B11: 3 | C11: =IF($L$1=0,0,IF(ISERROR(VLOOKUP($U$11&"-"&B11,'BD Seq Op'!C:H,2,FALSE)),0,VLOOKUP($U$11&"-"&B11,'BD Seq Op'!C:H,2,FALSE))) -> 0 | D11: =IF($L$1=0,0,IF(ISERROR(VLOOKUP($U$11&"-"&B11,'BD Seq Op'!C:H,5,FALSE)),0,VLOOKUP($U$11&"-"&B11,'BD Seq Op'!C:H,5,FALSE))) -> 0 | E11: =IF(C11=0,"",IF($U$1=TRUE,(60*$L$5)/D11,60/D11)) | H11: =IF(C11=0,"",IF($U$1=TRUE,$P$5,IF($L$2=0,$V$15,$L$2))) | I11: =IF(C11=0,"",IF(AE11=TRUE,0,D11*H11)) | R11: Ref. : | S11: =IF(L1=0,"",CONCATENATE(R11,U11)) | U11: =IF($L$1=0,"",IF(ISERROR(VLOOKUP($L$1,'BD da OP'!$A:$AC,4,FALSE)),"",VLOOKUP($L$1,'BD da OP'!$A:$AC,4,FALSE))) | AE11: FALSE
A12: =IF(C12=0,"Não","Sim") -> Não | B12: 4 | C12: =IF($L$1=0,0,IF(ISERROR(VLOOKUP($U$11&"-"&B12,'BD Seq Op'!C:H,2,FALSE)),0,VLOOKUP($U$11&"-"&B12,'BD Seq Op'!C:H,2,FALSE))) -> 0 | D12: =IF($L$1=0,0,IF(ISERROR(VLOOKUP($U$11&"-"&B12,'BD Seq Op'!C:H,5,FALSE)),0,VLOOKUP($U$11&"-"&B12,'BD Seq Op'!C:H,5,FALSE))) -> 0 | E12: =IF(C12=0,"",IF($U$1=TRUE,(60*$L$5)/D12,60/D12)) | H12: =IF(C12=0,"",IF($U$1=TRUE,$P$5,IF($L$2=0,$V$15,$L$2))) | I12: =IF(C12=0,"",IF(AE12=TRUE,0,D12*H12)) | R12: Descr. Ref. : | S12: =U12 | U12: =IF($L$1=0,"",IF(ISERROR(VLOOKUP(U11,Ref!A:B,2,FALSE)),"",VLOOKUP(U11,Ref!A:B,2,FALSE))) | AE12: FALSE
A13: =IF(C13=0,"Não","Sim") -> Não | B13: 5 | C13: =IF($L$1=0,0,IF(ISERROR(VLOOKUP($U$11&"-"&B13,'BD Seq Op'!C:H,2,FALSE)),0,VLOOKUP($U$11&"-"&B13,'BD Seq Op'!C:H,2,FALSE))) -> 0 | D13: =IF($L$1=0,0,IF(ISERROR(VLOOKUP($U$11&"-"&B13,'BD Seq Op'!C:H,5,FALSE)),0,VLOOKUP($U$11&"-"&B13,'BD Seq Op'!C:H,5,FALSE))) -> 0 | E13: =IF(C13=0,"",IF($U$1=TRUE,(60*$L$5)/D13,60/D13)) | H13: =IF(C13=0,"",IF($U$1=TRUE,$P$5,IF($L$2=0,$V$15,$L$2))) | I13: =IF(C13=0,"",IF(AE13=TRUE,0,D13*H13)) | R13: Cor : | S13: =IF(L1=0,"",IF(U2=TRUE,"",IF(N1=0,CONCATENATE(R13,U13),CONCATENATE(R13,N1)))) | U13: =IF($L$1=0,"",IF(ISERROR(VLOOKUP($L$1,'BD da OP'!$A:$AC,6,FALSE)),"",VLOOKUP($L$1,'BD da OP'!$A:$AC,6,FALSE))) | V13: =IF($L$1=0,"",IF(ISERROR(VLOOKUP($L$1,'BD da OP'!$A:$AC,7,FALSE)),"",VLOOKUP($L$1,'BD da OP'!$A:$AC,7,FALSE))) | W13: =IF($L$1=0,"",IF(ISERROR(VLOOKUP($L$1,'BD da OP'!$A:$AC,8,FALSE)),"",VLOOKUP($L$1,'BD da OP'!$A:$AC,8,FALSE))) | X13: =IF($L$1=0,"",IF(ISERROR(VLOOKUP($L$1,'BD da OP'!$A:$AC,9,FALSE)),"",VLOOKUP($L$1,'BD da OP'!$A:$AC,9,FALSE))) | Y13: =IF($L$1=0,"",IF(ISERROR(VLOOKUP($L$1,'BD da OP'!$A:$AC,10,FALSE)),"",VLOOKUP($L$1,'BD da OP'!$A:$AC,10,FALSE))) | Z13: =IF($L$1=0,"",IF(ISERROR(VLOOKUP($L$1,'BD da OP'!$A:$AC,11,FALSE)),"",VLOOKUP($L$1,'BD da OP'!$A:$AC,11,FALSE))) | AA13: =IF($L$1=0,"",IF(ISERROR(VLOOKUP($L$1,'BD da OP'!$A:$AC,12,FALSE)),"",VLOOKUP($L$1,'BD da OP'!$A:$AC,12,FALSE))) | AB13: =IF($L$1=0,"",IF(ISERROR(VLOOKUP($L$1,'BD da OP'!$A:$AC,13,FALSE)),"",VLOOKUP($L$1,'BD da OP'!$A:$AC,13,FALSE))) | AC13: =IF($L$1=0,"",IF(ISERROR(VLOOKUP($L$1,'BD da OP'!$A:$AC,14,FALSE)),"",VLOOKUP($L$1,'BD da OP'!$A:$AC,14,FALSE))) | AD13: =IF($L$1=0,"",IF(ISERROR(VLOOKUP($L$1,'BD da OP'!$A:$AC,15,FALSE)),"",VLOOKUP($L$1,'BD da OP'!$A:$AC,15,FALSE))) | AE13: FALSE
A14: =IF(C14=0,"Não","Sim") -> Não | B14: 6 | C14: =IF($L$1=0,0,IF(ISERROR(VLOOKUP($U$11&"-"&B14,'BD Seq Op'!C:H,2,FALSE)),0,VLOOKUP($U$11&"-"&B14,'BD Seq Op'!C:H,2,FALSE))) -> 0 | D14: =IF($L$1=0,0,IF(ISERROR(VLOOKUP($U$11&"-"&B14,'BD Seq Op'!C:H,5,FALSE)),0,VLOOKUP($U$11&"-"&B14,'BD Seq Op'!C:H,5,FALSE))) -> 0 | E14: =IF(C14=0,"",IF($U$1=TRUE,(60*$L$5)/D14,60/D14)) | H14: =IF(C14=0,"",IF($U$1=TRUE,$P$5,IF($L$2=0,$V$15,$L$2))) | I14: =IF(C14=0,"",IF(AE14=TRUE,0,D14*H14)) | R14: Tam. : | S14: =IF(L1=0,"",IF(U2=TRUE,"",IF(N2=0,CONCATENATE(R14,UPPER(U14)),CONCATENATE(R14,UPPER(N2))))) | U14: =IF($L$1=0,"",IF(ISERROR(VLOOKUP($L$1,'BD da OP'!$A:$AC,16,FALSE)),"",VLOOKUP($L$1,'BD da OP'!$A:$AC,16,FALSE))) | V14: =IF($L$1=0,"",IF(ISERROR(VLOOKUP($L$1,'BD da OP'!$A:$AC,17,FALSE)),"",VLOOKUP($L$1,'BD da OP'!$A:$AC,17,FALSE))) | W14: =IF($L$1=0,"",IF(ISERROR(VLOOKUP($L$1,'BD da OP'!$A:$AC,18,FALSE)),"",VLOOKUP($L$1,'BD da OP'!$A:$AC,18,FALSE))) | X14: =IF($L$1=0,"",IF(ISERROR(VLOOKUP($L$1,'BD da OP'!$A:$AC,19,FALSE)),"",VLOOKUP($L$1,'BD da OP'!$A:$AC,19,FALSE))) | Y14: =IF($L$1=0,"",IF(ISERROR(VLOOKUP($L$1,'BD da OP'!$A:$AC,20,FALSE)),"",VLOOKUP($L$1,'BD da OP'!$A:$AC,20,FALSE))) | Z14: =IF($L$1=0,"",IF(ISERROR(VLOOKUP($L$1,'BD da OP'!$A:$AC,21,FALSE)),"",VLOOKUP($L$1,'BD da OP'!$A:$AC,21,FALSE))) | AA14: =IF($L$1=0,"",IF(ISERROR(VLOOKUP($L$1,'BD da OP'!$A:$AC,22,FALSE)),"",VLOOKUP($L$1,'BD da OP'!$A:$AC,22,FALSE))) | AB14: =IF($L$1=0,"",IF(ISERROR(VLOOKUP($L$1,'BD da OP'!$A:$AC,23,FALSE)),"",VLOOKUP($L$1,'BD da OP'!$A:$AC,23,FALSE))) | AC14: =IF($L$1=0,"",IF(ISERROR(VLOOKUP($L$1,'BD da OP'!$A:$AC,24,FALSE)),"",VLOOKUP($L$1,'BD da OP'!$A:$AC,24,FALSE))) | AD14: =IF($L$1=0,"",IF(ISERROR(VLOOKUP($L$1,'BD da OP'!$A:$AC,25,FALSE)),"",VLOOKUP($L$1,'BD da OP'!$A:$AC,25,FALSE))) | AE14: FALSE
A15: =IF(C15=0,"Não","Sim") -> Não | B15: 7 | C15: =IF($L$1=0,0,IF(ISERROR(VLOOKUP($U$11&"-"&B15,'BD Seq Op'!C:H,2,FALSE)),0,VLOOKUP($U$11&"-"&B15,'BD Seq Op'!C:H,2,FALSE))) -> 0 | D15: =IF($L$1=0,0,IF(ISERROR(VLOOKUP($U$11&"-"&B15,'BD Seq Op'!C:H,5,FALSE)),0,VLOOKUP($U$11&"-"&B15,'BD Seq Op'!C:H,5,FALSE))) -> 0 | E15: =IF(C15=0,"",IF($U$1=TRUE,(60*$L$5)/D15,60/D15)) | H15: =IF(C15=0,"",IF($U$1=TRUE,$P$5,IF($L$2=0,$V$15,$L$2))) | I15: =IF(C15=0,"",IF(AE15=TRUE,0,D15*H15)) | R15: Qtde Peças : | S15: =IF(L1=0,"",IF(U15<1000,CONCATENATE(R15,U15),CONCATENATE(R15,TEXT(U15,"0.000")))) | U15: =IF(U1=TRUE,P5,IF(L2=0,V15,L2)) | V15: =IF($L$1=0,"",IF(ISERROR(VLOOKUP($L$1,'BD da OP'!$A:$AC,26,FALSE)),"",VLOOKUP($L$1,'BD da OP'!$A:$AC,26,FALSE))) | AE15: FALSE
A16: =IF(C16=0,"Não","Sim") -> Não | B16: 8 | C16: =IF($L$1=0,0,IF(ISERROR(VLOOKUP($U$11&"-"&B16,'BD Seq Op'!C:H,2,FALSE)),0,VLOOKUP($U$11&"-"&B16,'BD Seq Op'!C:H,2,FALSE))) -> 0 | D16: =IF($L$1=0,0,IF(ISERROR(VLOOKUP($U$11&"-"&B16,'BD Seq Op'!C:H,5,FALSE)),0,VLOOKUP($U$11&"-"&B16,'BD Seq Op'!C:H,5,FALSE))) -> 0 | E16: =IF(C16=0,"",IF($U$1=TRUE,(60*$L$5)/D16,60/D16)) | H16: =IF(C16=0,"",IF($U$1=TRUE,$P$5,IF($L$2=0,$V$15,$L$2))) | I16: =IF(C16=0,"",IF(AE16=TRUE,0,D16*H16)) | R16: =CONCATENATE(Cliente!F1," : ") -> Cliente : | S16: =IF(L1=0,"",IF(U16=0,"",CONCATENATE(R16,U16))) | U16: =IF($L$1=0,"",IF(ISERROR(VLOOKUP($L$1,'BD da OP'!$A:$AC,27,FALSE)),"",VLOOKUP($L$1,'BD da OP'!$A:$AC,27,FALSE))) | AE16: FALSE
A17: =IF(C17=0,"Não","Sim") -> Não | B17: 9 | C17: =IF($L$1=0,0,IF(ISERROR(VLOOKUP($U$11&"-"&B17,'BD Seq Op'!C:H,2,FALSE)),0,VLOOKUP($U$11&"-"&B17,'BD Seq Op'!C:H,2,FALSE))) -> 0 | D17: =IF($L$1=0,0,IF(ISERROR(VLOOKUP($U$11&"-"&B17,'BD Seq Op'!C:H,5,FALSE)),0,VLOOKUP($U$11&"-"&B17,'BD Seq Op'!C:H,5,FALSE))) -> 0 | E17: =IF(C17=0,"",IF($U$1=TRUE,(60*$L$5)/D17,60/D17)) | H17: =IF(C17=0,"",IF($U$1=TRUE,$P$5,IF($L$2=0,$V$15,$L$2))) | I17: =IF(C17=0,"",IF(AE17=TRUE,0,D17*H17)) | R17: Previsão Entrega : | S17: =IF(L1=0,"",IF(U17=0,"Previsão Entrega : não definida",CONCATENATE(R17,TEXT(U17,"dd/mm/aaaa")))) | U17: =IF($L$1=0,"",IF(ISERROR(VLOOKUP($L$1,'BD da OP'!$A:$AC,28,FALSE)),"",VLOOKUP($L$1,'BD da OP'!$A:$AC,28,FALSE))) | AE17: FALSE
A18: =IF(C18=0,"Não","Sim") -> Não | B18: 10 | C18: =IF($L$1=0,0,IF(ISERROR(VLOOKUP($U$11&"-"&B18,'BD Seq Op'!C:H,2,FALSE)),0,VLOOKUP($U$11&"-"&B18,'BD Seq Op'!C:H,2,FALSE))) -> 0 | D18: =IF($L$1=0,0,IF(ISERROR(VLOOKUP($U$11&"-"&B18,'BD Seq Op'!C:H,5,FALSE)),0,VLOOKUP($U$11&"-"&B18,'BD Seq Op'!C:H,5,FALSE))) -> 0 | E18: =IF(C18=0,"",IF($U$1=TRUE,(60*$L$5)/D18,60/D18)) | H18: =IF(C18=0,"",IF($U$1=TRUE,$P$5,IF($L$2=0,$V$15,$L$2))) | I18: =IF(C18=0,"",IF(AE18=TRUE,0,D18*H18)) | R18: Observações : | S18: =IF(U18=0,"",U18) | U18: =IF($L$1=0,"",IF(ISERROR(VLOOKUP($L$1,'BD da OP'!$A:$AC,29,FALSE)),"",VLOOKUP($L$1,'BD da OP'!$A:$AC,29,FALSE))) | AE18: FALSE
A19: =IF(C19=0,"Não","Sim") -> Não | B19: 11 | C19: =IF($L$1=0,0,IF(ISERROR(VLOOKUP($U$11&"-"&B19,'BD Seq Op'!C:H,2,FALSE)),0,VLOOKUP($U$11&"-"&B19,'BD Seq Op'!C:H,2,FALSE))) -> 0 | D19: =IF($L$1=0,0,IF(ISERROR(VLOOKUP($U$11&"-"&B19,'BD Seq Op'!C:H,5,FALSE)),0,VLOOKUP($U$11&"-"&B19,'BD Seq Op'!C:H,5,FALSE))) -> 0 | E19: =IF(C19=0,"",IF($U$1=TRUE,(60*$L$5)/D19,60/D19)) | H19: =IF(C19=0,"",IF($U$1=TRUE,$P$5,IF($L$2=0,$V$15,$L$2))) | I19: =IF(C19=0,"",IF(AE19=TRUE,0,D19*H19)) | AE19: FALSE
A20: =IF(C20=0,"Não","Sim") -> Não | B20: 12 | C20: =IF($L$1=0,0,IF(ISERROR(VLOOKUP($U$11&"-"&B20,'BD Seq Op'!C:H,2,FALSE)),0,VLOOKUP($U$11&"-"&B20,'BD Seq Op'!C:H,2,FALSE))) -> 0 | D20: =IF($L$1=0,0,IF(ISERROR(VLOOKUP($U$11&"-"&B20,'BD Seq Op'!C:H,5,FALSE)),0,VLOOKUP($U$11&"-"&B20,'BD Seq Op'!C:H,5,FALSE))) -> 0 | E20: =IF(C20=0,"",IF($U$1=TRUE,(60*$L$5)/D20,60/D20)) | H20: =IF(C20=0,"",IF($U$1=TRUE,$P$5,IF($L$2=0,$V$15,$L$2))) | I20: =IF(C20=0,"",IF(AE20=TRUE,0,D20*H20)) | AE20: FALSE
A21: =IF(C21=0,"Não","Sim") -> Não | B21: 13 | C21: =IF($L$1=0,0,IF(ISERROR(VLOOKUP($U$11&"-"&B21,'BD Seq Op'!C:H,2,FALSE)),0,VLOOKUP($U$11&"-"&B21,'BD Seq Op'!C:H,2,FALSE))) -> 0 | D21: =IF($L$1=0,0,IF(ISERROR(VLOOKUP($U$11&"-"&B21,'BD Seq Op'!C:H,5,FALSE)),0,VLOOKUP($U$11&"-"&B21,'BD Seq Op'!C:H,5,FALSE))) -> 0 | E21: =IF(C21=0,"",IF($U$1=TRUE,(60*$L$5)/D21,60/D21)) | H21: =IF(C21=0,"",IF($U$1=TRUE,$P$5,IF($L$2=0,$V$15,$L$2))) | I21: =IF(C21=0,"",IF(AE21=TRUE,0,D21*H21)) | AE21: FALSE
A22: =IF(C22=0,"Não","Sim") -> Não | B22: 14 | C22: =IF($L$1=0,0,IF(ISERROR(VLOOKUP($U$11&"-"&B22,'BD Seq Op'!C:H,2,FALSE)),0,VLOOKUP($U$11&"-"&B22,'BD Seq Op'!C:H,2,FALSE))) -> 0 | D22: =IF($L$1=0,0,IF(ISERROR(VLOOKUP($U$11&"-"&B22,'BD Seq Op'!C:H,5,FALSE)),0,VLOOKUP($U$11&"-"&B22,'BD Seq Op'!C:H,5,FALSE))) -> 0 | E22: =IF(C22=0,"",IF($U$1=TRUE,(60*$L$5)/D22,60/D22)) | H22: =IF(C22=0,"",IF($U$1=TRUE,$P$5,IF($L$2=0,$V$15,$L$2))) | I22: =IF(C22=0,"",IF(AE22=TRUE,0,D22*H22)) | AE22: FALSE
A23: =IF(C23=0,"Não","Sim") -> Não | B23: 15 | C23: =IF($L$1=0,0,IF(ISERROR(VLOOKUP($U$11&"-"&B23,'BD Seq Op'!C:H,2,FALSE)),0,VLOOKUP($U$11&"-"&B23,'BD Seq Op'!C:H,2,FALSE))) -> 0 | D23: =IF($L$1=0,0,IF(ISERROR(VLOOKUP($U$11&"-"&B23,'BD Seq Op'!C:H,5,FALSE)),0,VLOOKUP($U$11&"-"&B23,'BD Seq Op'!C:H,5,FALSE))) -> 0 | E23: =IF(C23=0,"",IF($U$1=TRUE,(60*$L$5)/D23,60/D23)) | H23: =IF(C23=0,"",IF($U$1=TRUE,$P$5,IF($L$2=0,$V$15,$L$2))) | I23: =IF(C23=0,"",IF(AE23=TRUE,0,D23*H23)) | AE23: FALSE
A24: =IF(C24=0,"Não","Sim") -> Não | B24: 16 | C24: =IF($L$1=0,0,IF(ISERROR(VLOOKUP($U$11&"-"&B24,'BD Seq Op'!C:H,2,FALSE)),0,VLOOKUP($U$11&"-"&B24,'BD Seq Op'!C:H,2,FALSE))) -> 0 | D24: =IF($L$1=0,0,IF(ISERROR(VLOOKUP($U$11&"-"&B24,'BD Seq Op'!C:H,5,FALSE)),0,VLOOKUP($U$11&"-"&B24,'BD Seq Op'!C:H,5,FALSE))) -> 0 | E24: =IF(C24=0,"",IF($U$1=TRUE,(60*$L$5)/D24,60/D24)) | H24: =IF(C24=0,"",IF($U$1=TRUE,$P$5,IF($L$2=0,$V$15,$L$2))) | I24: =IF(C24=0,"",IF(AE24=TRUE,0,D24*H24)) | AE24: FALSE
A25: =IF(C25=0,"Não","Sim") -> Não | B25: 17 | C25: =IF($L$1=0,0,IF(ISERROR(VLOOKUP($U$11&"-"&B25,'BD Seq Op'!C:H,2,FALSE)),0,VLOOKUP($U$11&"-"&B25,'BD Seq Op'!C:H,2,FALSE))) -> 0 | D25: =IF($L$1=0,0,IF(ISERROR(VLOOKUP($U$11&"-"&B25,'BD Seq Op'!C:H,5,FALSE)),0,VLOOKUP($U$11&"-"&B25,'BD Seq Op'!C:H,5,FALSE))) -> 0 | E25: =IF(C25=0,"",IF($U$1=TRUE,(60*$L$5)/D25,60/D25)) | H25: =IF(C25=0,"",IF($U$1=TRUE,$P$5,IF($L$2=0,$V$15,$L$2))) | I25: =IF(C25=0,"",IF(AE25=TRUE,0,D25*H25)) | AE25: FALSE
A26: =IF(C26=0,"Não","Sim") -> Não | B26: 18 | C26: =IF($L$1=0,0,IF(ISERROR(VLOOKUP($U$11&"-"&B26,'BD Seq Op'!C:H,2,FALSE)),0,VLOOKUP($U$11&"-"&B26,'BD Seq Op'!C:H,2,FALSE))) -> 0 | D26: =IF($L$1=0,0,IF(ISERROR(VLOOKUP($U$11&"-"&B26,'BD Seq Op'!C:H,5,FALSE)),0,VLOOKUP($U$11&"-"&B26,'BD Seq Op'!C:H,5,FALSE))) -> 0 | E26: =IF(C26=0,"",IF($U$1=TRUE,(60*$L$5)/D26,60/D26)) | H26: =IF(C26=0,"",IF($U$1=TRUE,$P$5,IF($L$2=0,$V$15,$L$2))) | I26: =IF(C26=0,"",IF(AE26=TRUE,0,D26*H26)) | AE26: FALSE
A27: =IF(C27=0,"Não","Sim") -> Não | B27: 19 | C27: =IF($L$1=0,0,IF(ISERROR(VLOOKUP($U$11&"-"&B27,'BD Seq Op'!C:H,2,FALSE)),0,VLOOKUP($U$11&"-"&B27,'BD Seq Op'!C:H,2,FALSE))) -> 0 | D27: =IF($L$1=0,0,IF(ISERROR(VLOOKUP($U$11&"-"&B27,'BD Seq Op'!C:H,5,FALSE)),0,VLOOKUP($U$11&"-"&B27,'BD Seq Op'!C:H,5,FALSE))) -> 0 | E27: =IF(C27=0,"",IF($U$1=TRUE,(60*$L$5)/D27,60/D27)) | H27: =IF(C27=0,"",IF($U$1=TRUE,$P$5,IF($L$2=0,$V$15,$L$2))) | I27: =IF(C27=0,"",IF(AE27=TRUE,0,D27*H27)) | AE27: FALSE
A28: =IF(C28=0,"Não","Sim") -> Não | B28: 20 | C28: =IF($L$1=0,0,IF(ISERROR(VLOOKUP($U$11&"-"&B28,'BD Seq Op'!C:H,2,FALSE)),0,VLOOKUP($U$11&"-"&B28,'BD Seq Op'!C:H,2,FALSE))) -> 0 | D28: =IF($L$1=0,0,IF(ISERROR(VLOOKUP($U$11&"-"&B28,'BD Seq Op'!C:H,5,FALSE)),0,VLOOKUP($U$11&"-"&B28,'BD Seq Op'!C:H,5,FALSE))) -> 0 | E28: =IF(C28=0,"",IF($U$1=TRUE,(60*$L$5)/D28,60/D28)) | H28: =IF(C28=0,"",IF($U$1=TRUE,$P$5,IF($L$2=0,$V$15,$L$2))) | I28: =IF(C28=0,"",IF(AE28=TRUE,0,D28*H28)) | AE28: FALSE
A29: =IF(C29=0,"Não","Sim") -> Não | B29: 21 | C29: =IF($L$1=0,0,IF(ISERROR(VLOOKUP($U$11&"-"&B29,'BD Seq Op'!C:H,2,FALSE)),0,VLOOKUP($U$11&"-"&B29,'BD Seq Op'!C:H,2,FALSE))) -> 0 | D29: =IF($L$1=0,0,IF(ISERROR(VLOOKUP($U$11&"-"&B29,'BD Seq Op'!C:H,5,FALSE)),0,VLOOKUP($U$11&"-"&B29,'BD Seq Op'!C:H,5,FALSE))) -> 0 | E29: =IF(C29=0,"",IF($U$1=TRUE,(60*$L$5)/D29,60/D29)) | H29: =IF(C29=0,"",IF($U$1=TRUE,$P$5,IF($L$2=0,$V$15,$L$2))) | I29: =IF(C29=0,"",IF(AE29=TRUE,0,D29*H29)) | AE29: FALSE
A30: =IF(C30=0,"Não","Sim") -> Não | B30: 22 | C30: =IF($L$1=0,0,IF(ISERROR(VLOOKUP($U$11&"-"&B30,'BD Seq Op'!C:H,2,FALSE)),0,VLOOKUP($U$11&"-"&B30,'BD Seq Op'!C:H,2,FALSE))) -> 0 | D30: =IF($L$1=0,0,IF(ISERROR(VLOOKUP($U$11&"-"&B30,'BD Seq Op'!C:H,5,FALSE)),0,VLOOKUP($U$11&"-"&B30,'BD Seq Op'!C:H,5,FALSE))) -> 0 | E30: =IF(C30=0,"",IF($U$1=TRUE,(60*$L$5)/D30,60/D30)) | H30: =IF(C30=0,"",IF($U$1=TRUE,$P$5,IF($L$2=0,$V$15,$L$2))) | I30: =IF(C30=0,"",IF(AE30=TRUE,0,D30*H30)) | AE30: FALSE
... A128: =IF(C128=0,"Não","Sim") -> Não | B128: 120 | C128: =IF($L$1=0,0,IF(ISERROR(VLOOKUP($U$11&"-"&B128,'BD Seq Op'!C:H,2,FALSE)),0,VLOOKUP($U$11&"-"&B128,'BD Seq Op'!C:H,2,FALSE))) -> 0 | D128: =IF($L$1=0,0,IF(ISERROR(VLOOKUP($U$11&"-"&B128,'BD Seq Op'!C:H,5,FALSE)),0,VLOOKUP($U$11&"-"&B128,'BD Seq Op'!C:H,5,FALSE))) -> 0 | E128: =IF(C128=0,"",IF($U$1=TRUE,(60*$L$5)/D128,60/D128)) | H128: =IF(C128=0,"",IF($U$1=TRUE,$P$5,IF($L$2=0,$V$15,$L$2))) | I128: =IF(C128=0,"",IF(AE128=TRUE,0,D128*H128)) | AE128: FALSE
A129: Sim | E129: Tempo total => | F129: =SUBTOTAL(9,I9:I128) -> 0

Sheet Balanceamento
C1: Ficha de Balanceamento | H1: Qtde pçs/dia: | K1: =TODAY() -> 46133
H2: =IF(K3=0,"Min. Trab./dia:","Min. Trab./dia/turno:") -> Min. Trab./dia/turno: | R2: =IF(C2=0,"",IF(ISERROR(VLOOKUP(C2,'BD Seq Op'!B:H,1,FALSE)),"Não cadastrada.",""))
C3: =IF(C2=0,"",VLOOKUP(C2,Ref!A:B,2,FALSE)) | H3: =IF(R5=2,"% Efic. p/ Máq.: ","% Efic. Geral: ") -> % Efic. p/ Máq.: | K3: Qtde de Turno | R3: 1
A4: Filtro | B4: Seq. | C4: Descrição operacional | D4: Tipo Máq. | E4: Tipo Apar. | F4: Tempo Padrão | G4: % Efic. | H4: Produção pçs/Hora | I4: Qtde de Máq. | J4: Qtde de Operad. | K4: Observações
A5: Sim | B5: Seq. | C5: Descrição operacional | D5: Tipo Máq. | E5: Tipo Apar. | F5: Tempo Padrão | G5: % Efic. Máq. | H5: =IF(R3=1,"Pçs/Hora 100%",IF(R3=2,"Pçs/Hora"&TEXT(I3," 0%"),"Pçs/Hora Efic. Máq.")) -> Pçs/Hora 100% | I5: Qtde Máq. | J5: Qtde Oper. | K5: Observações | R5: 2
A6: =IF(C6="","Não","Sim") -> Não | B6: 1 | C6: =IF($C$2=0,"",IF(ISERROR(VLOOKUP($C$2&"-"&$B6,'BD Seq Op'!$C:$H,2,FALSE)),"",VLOOKUP($C$2&"-"&$B6,'BD Seq Op'!$C:$H,2,FALSE))) | D6: =IF($C$2=0,"",IF(ISERROR(VLOOKUP($C$2&"-"&$B6,'BD Seq Op'!$C:$H,3,FALSE)),"",VLOOKUP($C$2&"-"&$B6,'BD Seq Op'!$C:$H,3,FALSE))) | E6: =IF($C$2=0,"",IF(ISERROR(VLOOKUP($C$2&"-"&$B6,'BD Seq Op'!$C:$H,4,FALSE)),"",VLOOKUP($C$2&"-"&$B6,'BD Seq Op'!$C:$H,4,FALSE))) | F6: =IF($C$2=0,"",IF(ISERROR(VLOOKUP($C$2&"-"&$B6,'BD Seq Op'!$C:$H,5,FALSE)),"",VLOOKUP($C$2&"-"&$B6,'BD Seq Op'!$C:$H,5,FALSE))) | G6: =IF(D6="","",VLOOKUP(D6,Máquinas!A:C,3,FALSE)) | H6: =IF(F6="","",IF($R$3=1,60/F6,IF($R$3=2,(60*$I$3)/F6,(60*G6)/F6))) | I6: =IF(F6="",0,IF($I$2=0,0,IF($J$3=0,0,IF($R$5=2,(F6*$I$1/(($J$3*$I$2)*G6)),IF($I$3=0,0,(F6*$I$1/(($J$3*$I$2)*$I$3))))))) -> 0 | J6: =IF(I6=0,0,I6*$J$3) -> 0 | M6: Resumo Máquinas | R6: =IF($R$5=1,"% Efic. Geral","% Efic. p/ Máq.") -> % Efic. p/ Máq.
A7: =IF(C7="","Não","Sim") -> Não | B7: 2 | C7: =IF($C$2=0,"",IF(ISERROR(VLOOKUP($C$2&"-"&$B7,'BD Seq Op'!$C:$H,2,FALSE)),"",VLOOKUP($C$2&"-"&$B7,'BD Seq Op'!$C:$H,2,FALSE))) | D7: =IF($C$2=0,"",IF(ISERROR(VLOOKUP($C$2&"-"&$B7,'BD Seq Op'!$C:$H,3,FALSE)),"",VLOOKUP($C$2&"-"&$B7,'BD Seq Op'!$C:$H,3,FALSE))) | E7: =IF($C$2=0,"",IF(ISERROR(VLOOKUP($C$2&"-"&$B7,'BD Seq Op'!$C:$H,4,FALSE)),"",VLOOKUP($C$2&"-"&$B7,'BD Seq Op'!$C:$H,4,FALSE))) | F7: =IF($C$2=0,"",IF(ISERROR(VLOOKUP($C$2&"-"&$B7,'BD Seq Op'!$C:$H,5,FALSE)),"",VLOOKUP($C$2&"-"&$B7,'BD Seq Op'!$C:$H,5,FALSE))) | G7: =IF(D7="","",VLOOKUP(D7,Máquinas!A:C,3,FALSE)) | H7: =IF(F7="","",IF($R$3=1,60/F7,IF($R$3=2,(60*$I$3)/F7,(60*G7)/F7))) | I7: =IF(F7="",0,IF($I$2=0,0,IF($J$3=0,0,IF($R$5=2,(F7*$I$1/(($J$3*$I$2)*G7)),IF($I$3=0,0,(F7*$I$1/(($J$3*$I$2)*$I$3))))))) -> 0 | J7: =IF(I7=0,0,I7*$J$3) -> 0 | M7: Tipo Máq. | N7: Qtde | R7: =IF($R$3=1,"Pçs/Hora 100% **",IF($R$3=2,"Pçs/Hora com % Efic. Geral **","Pçs/Hora com % Efic. Máq. **")) -> Pçs/Hora 100% **
A8: =IF(C8="","Não","Sim") -> Não | B8: 3 | C8: =IF($C$2=0,"",IF(ISERROR(VLOOKUP($C$2&"-"&$B8,'BD Seq Op'!$C:$H,2,FALSE)),"",VLOOKUP($C$2&"-"&$B8,'BD Seq Op'!$C:$H,2,FALSE))) | D8: =IF($C$2=0,"",IF(ISERROR(VLOOKUP($C$2&"-"&$B8,'BD Seq Op'!$C:$H,3,FALSE)),"",VLOOKUP($C$2&"-"&$B8,'BD Seq Op'!$C:$H,3,FALSE))) | E8: =IF($C$2=0,"",IF(ISERROR(VLOOKUP($C$2&"-"&$B8,'BD Seq Op'!$C:$H,4,FALSE)),"",VLOOKUP($C$2&"-"&$B8,'BD Seq Op'!$C:$H,4,FALSE))) | F8: =IF($C$2=0,"",IF(ISERROR(VLOOKUP($C$2&"-"&$B8,'BD Seq Op'!$C:$H,5,FALSE)),"",VLOOKUP($C$2&"-"&$B8,'BD Seq Op'!$C:$H,5,FALSE))) | G8: =IF(D8="","",VLOOKUP(D8,Máquinas!A:C,3,FALSE)) | H8: =IF(F8="","",IF($R$3=1,60/F8,IF($R$3=2,(60*$I$3)/F8,(60*G8)/F8))) | I8: =IF(F8="",0,IF($I$2=0,0,IF($J$3=0,0,IF($R$5=2,(F8*$I$1/(($J$3*$I$2)*G8)),IF($I$3=0,0,(F8*$I$1/(($J$3*$I$2)*$I$3))))))) -> 0 | J8: =IF(I8=0,0,I8*$J$3) -> 0 | N8: =SUMIF($D$6:$D$125,M8,$I$6:$I$125) -> 0 | R8: =IF(AND(I3=0,R5=1),"Informe a Eficiência","")
A9: =IF(C9="","Não","Sim") -> Não | B9: 4 | C9: =IF($C$2=0,"",IF(ISERROR(VLOOKUP($C$2&"-"&$B9,'BD Seq Op'!$C:$H,2,FALSE)),"",VLOOKUP($C$2&"-"&$B9,'BD Seq Op'!$C:$H,2,FALSE))) | D9: =IF($C$2=0,"",IF(ISERROR(VLOOKUP($C$2&"-"&$B9,'BD Seq Op'!$C:$H,3,FALSE)),"",VLOOKUP($C$2&"-"&$B9,'BD Seq Op'!$C:$H,3,FALSE))) | E9: =IF($C$2=0,"",IF(ISERROR(VLOOKUP($C$2&"-"&$B9,'BD Seq Op'!$C:$H,4,FALSE)),"",VLOOKUP($C$2&"-"&$B9,'BD Seq Op'!$C:$H,4,FALSE))) | F9: =IF($C$2=0,"",IF(ISERROR(VLOOKUP($C$2&"-"&$B9,'BD Seq Op'!$C:$H,5,FALSE)),"",VLOOKUP($C$2&"-"&$B9,'BD Seq Op'!$C:$H,5,FALSE))) | G9: =IF(D9="","",VLOOKUP(D9,Máquinas!A:C,3,FALSE)) | H9: =IF(F9="","",IF($R$3=1,60/F9,IF($R$3=2,(60*$I$3)/F9,(60*G9)/F9))) | I9: =IF(F9="",0,IF($I$2=0,0,IF($J$3=0,0,IF($R$5=2,(F9*$I$1/(($J$3*$I$2)*G9)),IF($I$3=0,0,(F9*$I$1/(($J$3*$I$2)*$I$3))))))) -> 0 | J9: =IF(I9=0,0,I9*$J$3) -> 0 | N9: =SUMIF($D$6:$D$125,M9,$I$6:$I$125) -> 0
A10: =IF(C10="","Não","Sim") -> Não | B10: 5 | C10: =IF($C$2=0,"",IF(ISERROR(VLOOKUP($C$2&"-"&$B10,'BD Seq Op'!$C:$H,2,FALSE)),"",VLOOKUP($C$2&"-"&$B10,'BD Seq Op'!$C:$H,2,FALSE))) | D10: =IF($C$2=0,"",IF(ISERROR(VLOOKUP($C$2&"-"&$B10,'BD Seq Op'!$C:$H,3,FALSE)),"",VLOOKUP($C$2&"-"&$B10,'BD Seq Op'!$C:$H,3,FALSE))) | E10: =IF($C$2=0,"",IF(ISERROR(VLOOKUP($C$2&"-"&$B10,'BD Seq Op'!$C:$H,4,FALSE)),"",VLOOKUP($C$2&"-"&$B10,'BD Seq Op'!$C:$H,4,FALSE))) | F10: =IF($C$2=0,"",IF(ISERROR(VLOOKUP($C$2&"-"&$B10,'BD Seq Op'!$C:$H,5,FALSE)),"",VLOOKUP($C$2&"-"&$B10,'BD Seq Op'!$C:$H,5,FALSE))) | G10: =IF(D10="","",VLOOKUP(D10,Máquinas!A:C,3,FALSE)) | H10: =IF(F10="","",IF($R$3=1,60/F10,IF($R$3=2,(60*$I$3)/F10,(60*G10)/F10))) | I10: =IF(F10="",0,IF($I$2=0,0,IF($J$3=0,0,IF($R$5=2,(F10*$I$1/(($J$3*$I$2)*G10)),IF($I$3=0,0,(F10*$I$1/(($J$3*$I$2)*$I$3))))))) -> 0 | J10: =IF(I10=0,0,I10*$J$3) -> 0 | N10: =SUMIF($D$6:$D$125,M10,$I$6:$I$125) -> 0
A11: =IF(C11="","Não","Sim") -> Não | B11: 6 | C11: =IF($C$2=0,"",IF(ISERROR(VLOOKUP($C$2&"-"&$B11,'BD Seq Op'!$C:$H,2,FALSE)),"",VLOOKUP($C$2&"-"&$B11,'BD Seq Op'!$C:$H,2,FALSE))) | D11: =IF($C$2=0,"",IF(ISERROR(VLOOKUP($C$2&"-"&$B11,'BD Seq Op'!$C:$H,3,FALSE)),"",VLOOKUP($C$2&"-"&$B11,'BD Seq Op'!$C:$H,3,FALSE))) | E11: =IF($C$2=0,"",IF(ISERROR(VLOOKUP($C$2&"-"&$B11,'BD Seq Op'!$C:$H,4,FALSE)),"",VLOOKUP($C$2&"-"&$B11,'BD Seq Op'!$C:$H,4,FALSE))) | F11: =IF($C$2=0,"",IF(ISERROR(VLOOKUP($C$2&"-"&$B11,'BD Seq Op'!$C:$H,5,FALSE)),"",VLOOKUP($C$2&"-"&$B11,'BD Seq Op'!$C:$H,5,FALSE))) | G11: =IF(D11="","",VLOOKUP(D11,Máquinas!A:C,3,FALSE)) | H11: =IF(F11="","",IF($R$3=1,60/F11,IF($R$3=2,(60*$I$3)/F11,(60*G11)/F11))) | I11: =IF(F11="",0,IF($I$2=0,0,IF($J$3=0,0,IF($R$5=2,(F11*$I$1/(($J$3*$I$2)*G11)),IF($I$3=0,0,(F11*$I$1/(($J$3*$I$2)*$I$3))))))) -> 0 | J11: =IF(I11=0,0,I11*$J$3) -> 0 | N11: =SUMIF($D$6:$D$125,M11,$I$6:$I$125) -> 0
A12: =IF(C12="","Não","Sim") -> Não | B12: 7 | C12: =IF($C$2=0,"",IF(ISERROR(VLOOKUP($C$2&"-"&$B12,'BD Seq Op'!$C:$H,2,FALSE)),"",VLOOKUP($C$2&"-"&$B12,'BD Seq Op'!$C:$H,2,FALSE))) | D12: =IF($C$2=0,"",IF(ISERROR(VLOOKUP($C$2&"-"&$B12,'BD Seq Op'!$C:$H,3,FALSE)),"",VLOOKUP($C$2&"-"&$B12,'BD Seq Op'!$C:$H,3,FALSE))) | E12: =IF($C$2=0,"",IF(ISERROR(VLOOKUP($C$2&"-"&$B12,'BD Seq Op'!$C:$H,4,FALSE)),"",VLOOKUP($C$2&"-"&$B12,'BD Seq Op'!$C:$H,4,FALSE))) | F12: =IF($C$2=0,"",IF(ISERROR(VLOOKUP($C$2&"-"&$B12,'BD Seq Op'!$C:$H,5,FALSE)),"",VLOOKUP($C$2&"-"&$B12,'BD Seq Op'!$C:$H,5,FALSE))) | G12: =IF(D12="","",VLOOKUP(D12,Máquinas!A:C,3,FALSE)) | H12: =IF(F12="","",IF($R$3=1,60/F12,IF($R$3=2,(60*$I$3)/F12,(60*G12)/F12))) | I12: =IF(F12="",0,IF($I$2=0,0,IF($J$3=0,0,IF($R$5=2,(F12*$I$1/(($J$3*$I$2)*G12)),IF($I$3=0,0,(F12*$I$1/(($J$3*$I$2)*$I$3))))))) -> 0 | J12: =IF(I12=0,0,I12*$J$3) -> 0 | N12: =SUMIF($D$6:$D$125,M12,$I$6:$I$125) -> 0
A13: =IF(C13="","Não","Sim") -> Não | B13: 8 | C13: =IF($C$2=0,"",IF(ISERROR(VLOOKUP($C$2&"-"&$B13,'BD Seq Op'!$C:$H,2,FALSE)),"",VLOOKUP($C$2&"-"&$B13,'BD Seq Op'!$C:$H,2,FALSE))) | D13: =IF($C$2=0,"",IF(ISERROR(VLOOKUP($C$2&"-"&$B13,'BD Seq Op'!$C:$H,3,FALSE)),"",VLOOKUP($C$2&"-"&$B13,'BD Seq Op'!$C:$H,3,FALSE))) | E13: =IF($C$2=0,"",IF(ISERROR(VLOOKUP($C$2&"-"&$B13,'BD Seq Op'!$C:$H,4,FALSE)),"",VLOOKUP($C$2&"-"&$B13,'BD Seq Op'!$C:$H,4,FALSE))) | F13: =IF($C$2=0,"",IF(ISERROR(VLOOKUP($C$2&"-"&$B13,'BD Seq Op'!$C:$H,5,FALSE)),"",VLOOKUP($C$2&"-"&$B13,'BD Seq Op'!$C:$H,5,FALSE))) | G13: =IF(D13="","",VLOOKUP(D13,Máquinas!A:C,3,FALSE)) | H13: =IF(F13="","",IF($R$3=1,60/F13,IF($R$3=2,(60*$I$3)/F13,(60*G13)/F13))) | I13: =IF(F13="",0,IF($I$2=0,0,IF($J$3=0,0,IF($R$5=2,(F13*$I$1/(($J$3*$I$2)*G13)),IF($I$3=0,0,(F13*$I$1/(($J$3*$I$2)*$I$3))))))) -> 0 | J13: =IF(I13=0,0,I13*$J$3) -> 0 | N13: =SUMIF($D$6:$D$125,M13,$I$6:$I$125) -> 0
A14: =IF(C14="","Não","Sim") -> Não | B14: 9 | C14: =IF($C$2=0,"",IF(ISERROR(VLOOKUP($C$2&"-"&$B14,'BD Seq Op'!$C:$H,2,FALSE)),"",VLOOKUP($C$2&"-"&$B14,'BD Seq Op'!$C:$H,2,FALSE))) | D14: =IF($C$2=0,"",IF(ISERROR(VLOOKUP($C$2&"-"&$B14,'BD Seq Op'!$C:$H,3,FALSE)),"",VLOOKUP($C$2&"-"&$B14,'BD Seq Op'!$C:$H,3,FALSE))) | E14: =IF($C$2=0,"",IF(ISERROR(VLOOKUP($C$2&"-"&$B14,'BD Seq Op'!$C:$H,4,FALSE)),"",VLOOKUP($C$2&"-"&$B14,'BD Seq Op'!$C:$H,4,FALSE))) | F14: =IF($C$2=0,"",IF(ISERROR(VLOOKUP($C$2&"-"&$B14,'BD Seq Op'!$C:$H,5,FALSE)),"",VLOOKUP($C$2&"-"&$B14,'BD Seq Op'!$C:$H,5,FALSE))) | G14: =IF(D14="","",VLOOKUP(D14,Máquinas!A:C,3,FALSE)) | H14: =IF(F14="","",IF($R$3=1,60/F14,IF($R$3=2,(60*$I$3)/F14,(60*G14)/F14))) | I14: =IF(F14="",0,IF($I$2=0,0,IF($J$3=0,0,IF($R$5=2,(F14*$I$1/(($J$3*$I$2)*G14)),IF($I$3=0,0,(F14*$I$1/(($J$3*$I$2)*$I$3))))))) -> 0 | J14: =IF(I14=0,0,I14*$J$3) -> 0 | N14: =SUMIF($D$6:$D$125,M14,$I$6:$I$125) -> 0
A15: =IF(C15="","Não","Sim") -> Não | B15: 10 | C15: =IF($C$2=0,"",IF(ISERROR(VLOOKUP($C$2&"-"&$B15,'BD Seq Op'!$C:$H,2,FALSE)),"",VLOOKUP($C$2&"-"&$B15,'BD Seq Op'!$C:$H,2,FALSE))) | D15: =IF($C$2=0,"",IF(ISERROR(VLOOKUP($C$2&"-"&$B15,'BD Seq Op'!$C:$H,3,FALSE)),"",VLOOKUP($C$2&"-"&$B15,'BD Seq Op'!$C:$H,3,FALSE))) | E15: =IF($C$2=0,"",IF(ISERROR(VLOOKUP($C$2&"-"&$B15,'BD Seq Op'!$C:$H,4,FALSE)),"",VLOOKUP($C$2&"-"&$B15,'BD Seq Op'!$C:$H,4,FALSE))) | F15: =IF($C$2=0,"",IF(ISERROR(VLOOKUP($C$2&"-"&$B15,'BD Seq Op'!$C:$H,5,FALSE)),"",VLOOKUP($C$2&"-"&$B15,'BD Seq Op'!$C:$H,5,FALSE))) | G15: =IF(D15="","",VLOOKUP(D15,Máquinas!A:C,3,FALSE)) | H15: =IF(F15="","",IF($R$3=1,60/F15,IF($R$3=2,(60*$I$3)/F15,(60*G15)/F15))) | I15: =IF(F15="",0,IF($I$2=0,0,IF($J$3=0,0,IF($R$5=2,(F15*$I$1/(($J$3*$I$2)*G15)),IF($I$3=0,0,(F15*$I$1/(($J$3*$I$2)*$I$3))))))) -> 0 | J15: =IF(I15=0,0,I15*$J$3) -> 0 | N15: =SUMIF($D$6:$D$125,M15,$I$6:$I$125) -> 0
A16: =IF(C16="","Não","Sim") -> Não | B16: 11 | C16: =IF($C$2=0,"",IF(ISERROR(VLOOKUP($C$2&"-"&$B16,'BD Seq Op'!$C:$H,2,FALSE)),"",VLOOKUP($C$2&"-"&$B16,'BD Seq Op'!$C:$H,2,FALSE))) | D16: =IF($C$2=0,"",IF(ISERROR(VLOOKUP($C$2&"-"&$B16,'BD Seq Op'!$C:$H,3,FALSE)),"",VLOOKUP($C$2&"-"&$B16,'BD Seq Op'!$C:$H,3,FALSE))) | E16: =IF($C$2=0,"",IF(ISERROR(VLOOKUP($C$2&"-"&$B16,'BD Seq Op'!$C:$H,4,FALSE)),"",VLOOKUP($C$2&"-"&$B16,'BD Seq Op'!$C:$H,4,FALSE))) | F16: =IF($C$2=0,"",IF(ISERROR(VLOOKUP($C$2&"-"&$B16,'BD Seq Op'!$C:$H,5,FALSE)),"",VLOOKUP($C$2&"-"&$B16,'BD Seq Op'!$C:$H,5,FALSE))) | G16: =IF(D16="","",VLOOKUP(D16,Máquinas!A:C,3,FALSE)) | H16: =IF(F16="","",IF($R$3=1,60/F16,IF($R$3=2,(60*$I$3)/F16,(60*G16)/F16))) | I16: =IF(F16="",0,IF($I$2=0,0,IF($J$3=0,0,IF($R$5=2,(F16*$I$1/(($J$3*$I$2)*G16)),IF($I$3=0,0,(F16*$I$1/(($J$3*$I$2)*$I$3))))))) -> 0 | J16: =IF(I16=0,0,I16*$J$3) -> 0 | N16: =SUMIF($D$6:$D$125,M16,$I$6:$I$125) -> 0
A17: =IF(C17="","Não","Sim") -> Não | B17: 12 | C17: =IF($C$2=0,"",IF(ISERROR(VLOOKUP($C$2&"-"&$B17,'BD Seq Op'!$C:$H,2,FALSE)),"",VLOOKUP($C$2&"-"&$B17,'BD Seq Op'!$C:$H,2,FALSE))) | D17: =IF($C$2=0,"",IF(ISERROR(VLOOKUP($C$2&"-"&$B17,'BD Seq Op'!$C:$H,3,FALSE)),"",VLOOKUP($C$2&"-"&$B17,'BD Seq Op'!$C:$H,3,FALSE))) | E17: =IF($C$2=0,"",IF(ISERROR(VLOOKUP($C$2&"-"&$B17,'BD Seq Op'!$C:$H,4,FALSE)),"",VLOOKUP($C$2&"-"&$B17,'BD Seq Op'!$C:$H,4,FALSE))) | F17: =IF($C$2=0,"",IF(ISERROR(VLOOKUP($C$2&"-"&$B17,'BD Seq Op'!$C:$H,5,FALSE)),"",VLOOKUP($C$2&"-"&$B17,'BD Seq Op'!$C:$H,5,FALSE))) | G17: =IF(D17="","",VLOOKUP(D17,Máquinas!A:C,3,FALSE)) | H17: =IF(F17="","",IF($R$3=1,60/F17,IF($R$3=2,(60*$I$3)/F17,(60*G17)/F17))) | I17: =IF(F17="",0,IF($I$2=0,0,IF($J$3=0,0,IF($R$5=2,(F17*$I$1/(($J$3*$I$2)*G17)),IF($I$3=0,0,(F17*$I$1/(($J$3*$I$2)*$I$3))))))) -> 0 | J17: =IF(I17=0,0,I17*$J$3) -> 0 | N17: =SUMIF($D$6:$D$125,M17,$I$6:$I$125) -> 0
A18: =IF(C18="","Não","Sim") -> Não | B18: 13 | C18: =IF($C$2=0,"",IF(ISERROR(VLOOKUP($C$2&"-"&$B18,'BD Seq Op'!$C:$H,2,FALSE)),"",VLOOKUP($C$2&"-"&$B18,'BD Seq Op'!$C:$H,2,FALSE))) | D18: =IF($C$2=0,"",IF(ISERROR(VLOOKUP($C$2&"-"&$B18,'BD Seq Op'!$C:$H,3,FALSE)),"",VLOOKUP($C$2&"-"&$B18,'BD Seq Op'!$C:$H,3,FALSE))) | E18: =IF($C$2=0,"",IF(ISERROR(VLOOKUP($C$2&"-"&$B18,'BD Seq Op'!$C:$H,4,FALSE)),"",VLOOKUP($C$2&"-"&$B18,'BD Seq Op'!$C:$H,4,FALSE))) | F18: =IF($C$2=0,"",IF(ISERROR(VLOOKUP($C$2&"-"&$B18,'BD Seq Op'!$C:$H,5,FALSE)),"",VLOOKUP($C$2&"-"&$B18,'BD Seq Op'!$C:$H,5,FALSE))) | G18: =IF(D18="","",VLOOKUP(D18,Máquinas!A:C,3,FALSE)) | H18: =IF(F18="","",IF($R$3=1,60/F18,IF($R$3=2,(60*$I$3)/F18,(60*G18)/F18))) | I18: =IF(F18="",0,IF($I$2=0,0,IF($J$3=0,0,IF($R$5=2,(F18*$I$1/(($J$3*$I$2)*G18)),IF($I$3=0,0,(F18*$I$1/(($J$3*$I$2)*$I$3))))))) -> 0 | J18: =IF(I18=0,0,I18*$J$3) -> 0
A19: =IF(C19="","Não","Sim") -> Não | B19: 14 | C19: =IF($C$2=0,"",IF(ISERROR(VLOOKUP($C$2&"-"&$B19,'BD Seq Op'!$C:$H,2,FALSE)),"",VLOOKUP($C$2&"-"&$B19,'BD Seq Op'!$C:$H,2,FALSE))) | D19: =IF($C$2=0,"",IF(ISERROR(VLOOKUP($C$2&"-"&$B19,'BD Seq Op'!$C:$H,3,FALSE)),"",VLOOKUP($C$2&"-"&$B19,'BD Seq Op'!$C:$H,3,FALSE))) | E19: =IF($C$2=0,"",IF(ISERROR(VLOOKUP($C$2&"-"&$B19,'BD Seq Op'!$C:$H,4,FALSE)),"",VLOOKUP($C$2&"-"&$B19,'BD Seq Op'!$C:$H,4,FALSE))) | F19: =IF($C$2=0,"",IF(ISERROR(VLOOKUP($C$2&"-"&$B19,'BD Seq Op'!$C:$H,5,FALSE)),"",VLOOKUP($C$2&"-"&$B19,'BD Seq Op'!$C:$H,5,FALSE))) | G19: =IF(D19="","",VLOOKUP(D19,Máquinas!A:C,3,FALSE)) | H19: =IF(F19="","",IF($R$3=1,60/F19,IF($R$3=2,(60*$I$3)/F19,(60*G19)/F19))) | I19: =IF(F19="",0,IF($I$2=0,0,IF($J$3=0,0,IF($R$5=2,(F19*$I$1/(($J$3*$I$2)*G19)),IF($I$3=0,0,(F19*$I$1/(($J$3*$I$2)*$I$3))))))) -> 0 | J19: =IF(I19=0,0,I19*$J$3) -> 0
A20: =IF(C20="","Não","Sim") -> Não | B20: 15 | C20: =IF($C$2=0,"",IF(ISERROR(VLOOKUP($C$2&"-"&$B20,'BD Seq Op'!$C:$H,2,FALSE)),"",VLOOKUP($C$2&"-"&$B20,'BD Seq Op'!$C:$H,2,FALSE))) | D20: =IF($C$2=0,"",IF(ISERROR(VLOOKUP($C$2&"-"&$B20,'BD Seq Op'!$C:$H,3,FALSE)),"",VLOOKUP($C$2&"-"&$B20,'BD Seq Op'!$C:$H,3,FALSE))) | E20: =IF($C$2=0,"",IF(ISERROR(VLOOKUP($C$2&"-"&$B20,'BD Seq Op'!$C:$H,4,FALSE)),"",VLOOKUP($C$2&"-"&$B20,'BD Seq Op'!$C:$H,4,FALSE))) | F20: =IF($C$2=0,"",IF(ISERROR(VLOOKUP($C$2&"-"&$B20,'BD Seq Op'!$C:$H,5,FALSE)),"",VLOOKUP($C$2&"-"&$B20,'BD Seq Op'!$C:$H,5,FALSE))) | G20: =IF(D20="","",VLOOKUP(D20,Máquinas!A:C,3,FALSE)) | H20: =IF(F20="","",IF($R$3=1,60/F20,IF($R$3=2,(60*$I$3)/F20,(60*G20)/F20))) | I20: =IF(F20="",0,IF($I$2=0,0,IF($J$3=0,0,IF($R$5=2,(F20*$I$1/(($J$3*$I$2)*G20)),IF($I$3=0,0,(F20*$I$1/(($J$3*$I$2)*$I$3))))))) -> 0 | J20: =IF(I20=0,0,I20*$J$3) -> 0
A21: =IF(C21="","Não","Sim") -> Não | B21: 16 | C21: =IF($C$2=0,"",IF(ISERROR(VLOOKUP($C$2&"-"&$B21,'BD Seq Op'!$C:$H,2,FALSE)),"",VLOOKUP($C$2&"-"&$B21,'BD Seq Op'!$C:$H,2,FALSE))) | D21: =IF($C$2=0,"",IF(ISERROR(VLOOKUP($C$2&"-"&$B21,'BD Seq Op'!$C:$H,3,FALSE)),"",VLOOKUP($C$2&"-"&$B21,'BD Seq Op'!$C:$H,3,FALSE))) | E21: =IF($C$2=0,"",IF(ISERROR(VLOOKUP($C$2&"-"&$B21,'BD Seq Op'!$C:$H,4,FALSE)),"",VLOOKUP($C$2&"-"&$B21,'BD Seq Op'!$C:$H,4,FALSE))) | F21: =IF($C$2=0,"",IF(ISERROR(VLOOKUP($C$2&"-"&$B21,'BD Seq Op'!$C:$H,5,FALSE)),"",VLOOKUP($C$2&"-"&$B21,'BD Seq Op'!$C:$H,5,FALSE))) | G21: =IF(D21="","",VLOOKUP(D21,Máquinas!A:C,3,FALSE)) | H21: =IF(F21="","",IF($R$3=1,60/F21,IF($R$3=2,(60*$I$3)/F21,(60*G21)/F21))) | I21: =IF(F21="",0,IF($I$2=0,0,IF($J$3=0,0,IF($R$5=2,(F21*$I$1/(($J$3*$I$2)*G21)),IF($I$3=0,0,(F21*$I$1/(($J$3*$I$2)*$I$3))))))) -> 0 | J21: =IF(I21=0,0,I21*$J$3) -> 0
A22: =IF(C22="","Não","Sim") -> Não | B22: 17 | C22: =IF($C$2=0,"",IF(ISERROR(VLOOKUP($C$2&"-"&$B22,'BD Seq Op'!$C:$H,2,FALSE)),"",VLOOKUP($C$2&"-"&$B22,'BD Seq Op'!$C:$H,2,FALSE))) | D22: =IF($C$2=0,"",IF(ISERROR(VLOOKUP($C$2&"-"&$B22,'BD Seq Op'!$C:$H,3,FALSE)),"",VLOOKUP($C$2&"-"&$B22,'BD Seq Op'!$C:$H,3,FALSE))) | E22: =IF($C$2=0,"",IF(ISERROR(VLOOKUP($C$2&"-"&$B22,'BD Seq Op'!$C:$H,4,FALSE)),"",VLOOKUP($C$2&"-"&$B22,'BD Seq Op'!$C:$H,4,FALSE))) | F22: =IF($C$2=0,"",IF(ISERROR(VLOOKUP($C$2&"-"&$B22,'BD Seq Op'!$C:$H,5,FALSE)),"",VLOOKUP($C$2&"-"&$B22,'BD Seq Op'!$C:$H,5,FALSE))) | G22: =IF(D22="","",VLOOKUP(D22,Máquinas!A:C,3,FALSE)) | H22: =IF(F22="","",IF($R$3=1,60/F22,IF($R$3=2,(60*$I$3)/F22,(60*G22)/F22))) | I22: =IF(F22="",0,IF($I$2=0,0,IF($J$3=0,0,IF($R$5=2,(F22*$I$1/(($J$3*$I$2)*G22)),IF($I$3=0,0,(F22*$I$1/(($J$3*$I$2)*$I$3))))))) -> 0 | J22: =IF(I22=0,0,I22*$J$3) -> 0
A23: =IF(C23="","Não","Sim") -> Não | B23: 18 | C23: =IF($C$2=0,"",IF(ISERROR(VLOOKUP($C$2&"-"&$B23,'BD Seq Op'!$C:$H,2,FALSE)),"",VLOOKUP($C$2&"-"&$B23,'BD Seq Op'!$C:$H,2,FALSE))) | D23: =IF($C$2=0,"",IF(ISERROR(VLOOKUP($C$2&"-"&$B23,'BD Seq Op'!$C:$H,3,FALSE)),"",VLOOKUP($C$2&"-"&$B23,'BD Seq Op'!$C:$H,3,FALSE))) | E23: =IF($C$2=0,"",IF(ISERROR(VLOOKUP($C$2&"-"&$B23,'BD Seq Op'!$C:$H,4,FALSE)),"",VLOOKUP($C$2&"-"&$B23,'BD Seq Op'!$C:$H,4,FALSE))) | F23: =IF($C$2=0,"",IF(ISERROR(VLOOKUP($C$2&"-"&$B23,'BD Seq Op'!$C:$H,5,FALSE)),"",VLOOKUP($C$2&"-"&$B23,'BD Seq Op'!$C:$H,5,FALSE))) | G23: =IF(D23="","",VLOOKUP(D23,Máquinas!A:C,3,FALSE)) | H23: =IF(F23="","",IF($R$3=1,60/F23,IF($R$3=2,(60*$I$3)/F23,(60*G23)/F23))) | I23: =IF(F23="",0,IF($I$2=0,0,IF($J$3=0,0,IF($R$5=2,(F23*$I$1/(($J$3*$I$2)*G23)),IF($I$3=0,0,(F23*$I$1/(($J$3*$I$2)*$I$3))))))) -> 0 | J23: =IF(I23=0,0,I23*$J$3) -> 0
A24: =IF(C24="","Não","Sim") -> Não | B24: 19 | C24: =IF($C$2=0,"",IF(ISERROR(VLOOKUP($C$2&"-"&$B24,'BD Seq Op'!$C:$H,2,FALSE)),"",VLOOKUP($C$2&"-"&$B24,'BD Seq Op'!$C:$H,2,FALSE))) | D24: =IF($C$2=0,"",IF(ISERROR(VLOOKUP($C$2&"-"&$B24,'BD Seq Op'!$C:$H,3,FALSE)),"",VLOOKUP($C$2&"-"&$B24,'BD Seq Op'!$C:$H,3,FALSE))) | E24: =IF($C$2=0,"",IF(ISERROR(VLOOKUP($C$2&"-"&$B24,'BD Seq Op'!$C:$H,4,FALSE)),"",VLOOKUP($C$2&"-"&$B24,'BD Seq Op'!$C:$H,4,FALSE))) | F24: =IF($C$2=0,"",IF(ISERROR(VLOOKUP($C$2&"-"&$B24,'BD Seq Op'!$C:$H,5,FALSE)),"",VLOOKUP($C$2&"-"&$B24,'BD Seq Op'!$C:$H,5,FALSE))) | G24: =IF(D24="","",VLOOKUP(D24,Máquinas!A:C,3,FALSE)) | H24: =IF(F24="","",IF($R$3=1,60/F24,IF($R$3=2,(60*$I$3)/F24,(60*G24)/F24))) | I24: =IF(F24="",0,IF($I$2=0,0,IF($J$3=0,0,IF($R$5=2,(F24*$I$1/(($J$3*$I$2)*G24)),IF($I$3=0,0,(F24*$I$1/(($J$3*$I$2)*$I$3))))))) -> 0 | J24: =IF(I24=0,0,I24*$J$3) -> 0
A25: =IF(C25="","Não","Sim") -> Não | B25: 20 | C25: =IF($C$2=0,"",IF(ISERROR(VLOOKUP($C$2&"-"&$B25,'BD Seq Op'!$C:$H,2,FALSE)),"",VLOOKUP($C$2&"-"&$B25,'BD Seq Op'!$C:$H,2,FALSE))) | D25: =IF($C$2=0,"",IF(ISERROR(VLOOKUP($C$2&"-"&$B25,'BD Seq Op'!$C:$H,3,FALSE)),"",VLOOKUP($C$2&"-"&$B25,'BD Seq Op'!$C:$H,3,FALSE))) | E25: =IF($C$2=0,"",IF(ISERROR(VLOOKUP($C$2&"-"&$B25,'BD Seq Op'!$C:$H,4,FALSE)),"",VLOOKUP($C$2&"-"&$B25,'BD Seq Op'!$C:$H,4,FALSE))) | F25: =IF($C$2=0,"",IF(ISERROR(VLOOKUP($C$2&"-"&$B25,'BD Seq Op'!$C:$H,5,FALSE)),"",VLOOKUP($C$2&"-"&$B25,'BD Seq Op'!$C:$H,5,FALSE))) | G25: =IF(D25="","",VLOOKUP(D25,Máquinas!A:C,3,FALSE)) | H25: =IF(F25="","",IF($R$3=1,60/F25,IF($R$3=2,(60*$I$3)/F25,(60*G25)/F25))) | I25: =IF(F25="",0,IF($I$2=0,0,IF($J$3=0,0,IF($R$5=2,(F25*$I$1/(($J$3*$I$2)*G25)),IF($I$3=0,0,(F25*$I$1/(($J$3*$I$2)*$I$3))))))) -> 0 | J25: =IF(I25=0,0,I25*$J$3) -> 0
A26: =IF(C26="","Não","Sim") -> Não | B26: 21 | C26: =IF($C$2=0,"",IF(ISERROR(VLOOKUP($C$2&"-"&$B26,'BD Seq Op'!$C:$H,2,FALSE)),"",VLOOKUP($C$2&"-"&$B26,'BD Seq Op'!$C:$H,2,FALSE))) | D26: =IF($C$2=0,"",IF(ISERROR(VLOOKUP($C$2&"-"&$B26,'BD Seq Op'!$C:$H,3,FALSE)),"",VLOOKUP($C$2&"-"&$B26,'BD Seq Op'!$C:$H,3,FALSE))) | E26: =IF($C$2=0,"",IF(ISERROR(VLOOKUP($C$2&"-"&$B26,'BD Seq Op'!$C:$H,4,FALSE)),"",VLOOKUP($C$2&"-"&$B26,'BD Seq Op'!$C:$H,4,FALSE))) | F26: =IF($C$2=0,"",IF(ISERROR(VLOOKUP($C$2&"-"&$B26,'BD Seq Op'!$C:$H,5,FALSE)),"",VLOOKUP($C$2&"-"&$B26,'BD Seq Op'!$C:$H,5,FALSE))) | G26: =IF(D26="","",VLOOKUP(D26,Máquinas!A:C,3,FALSE)) | H26: =IF(F26="","",IF($R$3=1,60/F26,IF($R$3=2,(60*$I$3)/F26,(60*G26)/F26))) | I26: =IF(F26="",0,IF($I$2=0,0,IF($J$3=0,0,IF($R$5=2,(F26*$I$1/(($J$3*$I$2)*G26)),IF($I$3=0,0,(F26*$I$1/(($J$3*$I$2)*$I$3))))))) -> 0 | J26: =IF(I26=0,0,I26*$J$3) -> 0
A27: =IF(C27="","Não","Sim") -> Não | B27: 22 | C27: =IF($C$2=0,"",IF(ISERROR(VLOOKUP($C$2&"-"&$B27,'BD Seq Op'!$C:$H,2,FALSE)),"",VLOOKUP($C$2&"-"&$B27,'BD Seq Op'!$C:$H,2,FALSE))) | D27: =IF($C$2=0,"",IF(ISERROR(VLOOKUP($C$2&"-"&$B27,'BD Seq Op'!$C:$H,3,FALSE)),"",VLOOKUP($C$2&"-"&$B27,'BD Seq Op'!$C:$H,3,FALSE))) | E27: =IF($C$2=0,"",IF(ISERROR(VLOOKUP($C$2&"-"&$B27,'BD Seq Op'!$C:$H,4,FALSE)),"",VLOOKUP($C$2&"-"&$B27,'BD Seq Op'!$C:$H,4,FALSE))) | F27: =IF($C$2=0,"",IF(ISERROR(VLOOKUP($C$2&"-"&$B27,'BD Seq Op'!$C:$H,5,FALSE)),"",VLOOKUP($C$2&"-"&$B27,'BD Seq Op'!$C:$H,5,FALSE))) | G27: =IF(D27="","",VLOOKUP(D27,Máquinas!A:C,3,FALSE)) | H27: =IF(F27="","",IF($R$3=1,60/F27,IF($R$3=2,(60*$I$3)/F27,(60*G27)/F27))) | I27: =IF(F27="",0,IF($I$2=0,0,IF($J$3=0,0,IF($R$5=2,(F27*$I$1/(($J$3*$I$2)*G27)),IF($I$3=0,0,(F27*$I$1/(($J$3*$I$2)*$I$3))))))) -> 0 | J27: =IF(I27=0,0,I27*$J$3) -> 0
A28: =IF(C28="","Não","Sim") -> Não | B28: 23 | C28: =IF($C$2=0,"",IF(ISERROR(VLOOKUP($C$2&"-"&$B28,'BD Seq Op'!$C:$H,2,FALSE)),"",VLOOKUP($C$2&"-"&$B28,'BD Seq Op'!$C:$H,2,FALSE))) | D28: =IF($C$2=0,"",IF(ISERROR(VLOOKUP($C$2&"-"&$B28,'BD Seq Op'!$C:$H,3,FALSE)),"",VLOOKUP($C$2&"-"&$B28,'BD Seq Op'!$C:$H,3,FALSE))) | E28: =IF($C$2=0,"",IF(ISERROR(VLOOKUP($C$2&"-"&$B28,'BD Seq Op'!$C:$H,4,FALSE)),"",VLOOKUP($C$2&"-"&$B28,'BD Seq Op'!$C:$H,4,FALSE))) | F28: =IF($C$2=0,"",IF(ISERROR(VLOOKUP($C$2&"-"&$B28,'BD Seq Op'!$C:$H,5,FALSE)),"",VLOOKUP($C$2&"-"&$B28,'BD Seq Op'!$C:$H,5,FALSE))) | G28: =IF(D28="","",VLOOKUP(D28,Máquinas!A:C,3,FALSE)) | H28: =IF(F28="","",IF($R$3=1,60/F28,IF($R$3=2,(60*$I$3)/F28,(60*G28)/F28))) | I28: =IF(F28="",0,IF($I$2=0,0,IF($J$3=0,0,IF($R$5=2,(F28*$I$1/(($J$3*$I$2)*G28)),IF($I$3=0,0,(F28*$I$1/(($J$3*$I$2)*$I$3))))))) -> 0 | J28: =IF(I28=0,0,I28*$J$3) -> 0
A29: =IF(C29="","Não","Sim") -> Não | B29: 24 | C29: =IF($C$2=0,"",IF(ISERROR(VLOOKUP($C$2&"-"&$B29,'BD Seq Op'!$C:$H,2,FALSE)),"",VLOOKUP($C$2&"-"&$B29,'BD Seq Op'!$C:$H,2,FALSE))) | D29: =IF($C$2=0,"",IF(ISERROR(VLOOKUP($C$2&"-"&$B29,'BD Seq Op'!$C:$H,3,FALSE)),"",VLOOKUP($C$2&"-"&$B29,'BD Seq Op'!$C:$H,3,FALSE))) | E29: =IF($C$2=0,"",IF(ISERROR(VLOOKUP($C$2&"-"&$B29,'BD Seq Op'!$C:$H,4,FALSE)),"",VLOOKUP($C$2&"-"&$B29,'BD Seq Op'!$C:$H,4,FALSE))) | F29: =IF($C$2=0,"",IF(ISERROR(VLOOKUP($C$2&"-"&$B29,'BD Seq Op'!$C:$H,5,FALSE)),"",VLOOKUP($C$2&"-"&$B29,'BD Seq Op'!$C:$H,5,FALSE))) | G29: =IF(D29="","",VLOOKUP(D29,Máquinas!A:C,3,FALSE)) | H29: =IF(F29="","",IF($R$3=1,60/F29,IF($R$3=2,(60*$I$3)/F29,(60*G29)/F29))) | I29: =IF(F29="",0,IF($I$2=0,0,IF($J$3=0,0,IF($R$5=2,(F29*$I$1/(($J$3*$I$2)*G29)),IF($I$3=0,0,(F29*$I$1/(($J$3*$I$2)*$I$3))))))) -> 0 | J29: =IF(I29=0,0,I29*$J$3) -> 0
... A125: =IF(C125="","Não","Sim") -> Não | B125: 120 | C125: =IF($C$2=0,"",IF(ISERROR(VLOOKUP($C$2&"-"&$B125,'BD Seq Op'!$C:$H,2,FALSE)),"",VLOOKUP($C$2&"-"&$B125,'BD Seq Op'!$C:$H,2,FALSE))) | D125: =IF($C$2=0,"",IF(ISERROR(VLOOKUP($C$2&"-"&$B125,'BD Seq Op'!$C:$H,3,FALSE)),"",VLOOKUP($C$2&"-"&$B125,'BD Seq Op'!$C:$H,3,FALSE))) | E125: =IF($C$2=0,"",IF(ISERROR(VLOOKUP($C$2&"-"&$B125,'BD Seq Op'!$C:$H,4,FALSE)),"",VLOOKUP($C$2&"-"&$B125,'BD Seq Op'!$C:$H,4,FALSE))) | F125: =IF($C$2=0,"",IF(ISERROR(VLOOKUP($C$2&"-"&$B125,'BD Seq Op'!$C:$H,5,FALSE)),"",VLOOKUP($C$2&"-"&$B125,'BD Seq Op'!$C:$H,5,FALSE))) | G125: =IF(D125="","",VLOOKUP(D125,Máquinas!A:C,3,FALSE)) | H125: =IF(F125="","",IF($R$3=1,60/F125,IF($R$3=2,(60*$I$3)/F125,(60*G125)/F125))) | I125: =IF(F125="",0,IF($I$2=0,0,IF($J$3=0,0,IF($R$5=2,(F125*$I$1/(($J$3*$I$2)*G125)),IF($I$3=0,0,(F125*$I$1/(($J$3*$I$2)*$I$3))))))) -> 0 | J125: =IF(I125=0,0,I125*$J$3) -> 0
A126: sim | B126: =IF(C2=0,"",CONCATENATE("** Calculado com: ",R6," e ",R7)) | E126: Totais => | F126: =SUM(F6:F125) -> 0 | I126: =SUM(I6:I125) -> 0 | J126: =SUM(J6:J125) -> 0

Sheet Cliente
A1: =F1 -> Cliente | B1: =CONCATENATE("Observações ",F1," nas OPs") -> Observações Cliente nas OPs | F1: Cliente
A2: Magazine de Confecções Ltda.
A3: Maria & Maria | B3: Utilizar etiquetas do Cliente. Colocar TAGs do Cliente nas peças quando embaladas.
A4: Pepe | B4: **** CLIENTE ESPECIAL **** Utilizar etiquetas de composição e bordada enviadas pelo Cliente. Colocar TAGs do Cliente nas peças quando forem embaladas.

Sheet OP
A1: Nº OP : | P1: =IF(B1=0,"não",IF(ISERROR(VLOOKUP(B1,'BD da OP'!A:A,1,FALSE)),"não",VLOOKUP(B1,'BD da OP'!A:A,1,FALSE))) -> não
A2: Data Emissão : | B2: =TODAY() -> 46133 | P2: =IF(B1=P1,"OP já cadastrada, se necessário poderá utilizar vírgula para diferenciar a mesma OP. Exemplo: OP 1234,1 / 1234,2 .....","")
A3: Referência : | C3: =IF(P1<>"não","",IF(B3=0,"",VLOOKUP(B3,Ref!A:B,2,FALSE))) | P3: =IF(B1=0,"- - - - - -",IF(B2=0,"- - - - - -",IF(B3=0,"- - - - - -","Cadastrar"))) -> - - - - - -
A4: Cores : | P4: =Cliente!F1 -> Cliente
A5: Tamanhos :
A6: Qtde de Peças :
